Workbook

Sheet 2023 Forecast Totals
A1: Type of Annuals per Month | P1: Totals
A2: Total hired billable technicans | D2: 26 | E2: 26 | F2: 26 | G2: 26 | H2: 26 | I2: 26 | J2: 26 | K2: 26 | L2: 26 | M2: 26 | N2: 26 | O2: 26 | P2: =AVERAGE(D2:O2) -> 26 | Q2: 30 | R2: 36 | S2: 36 | T2: 36 | U2: 36 | V2: 36 | W2: 36 | X2: 30 | Y2: 30 | Z2: 30 | AA2: 30 | AB2: 30 | AC2: =AVERAGE(Q2:AB2) -> 33 | AD2: 30 | AE2: 30 | AF2: 30 | AG2: 30 | AH2: 30 | AI2: 30 | AJ2: 30 | AK2: 30 | AL2: 30 | AM2: 30 | AN2: 30 | AO2: 30 | AP2: =AVERAGE(AD2:AO2) -> 30
A3: Months | D3: Jan | E3: Feb | F3: Mar | G3: Apr | H3: May | I3: Jun | J3: Jul | K3: Aug | L3: Sep | M3: Oct | N3: Nov | O3: Dec | P3: 2024 Totals | Q3: Jan | R3: Feb | S3: Mar | T3: Apr | U3: May | V3: Jun | W3: Jul | X3: Aug | Y3: Sep | Z3: Oct | AA3: Nov | AB3: Dec | AC3: 2025 Totals | AD3: Jan | AE3: Feb | AF3: Mar | AG3: Apr | AH3: May | AI3: Jun | AJ3: Jul | AK3: Aug | AL3: Sep | AM3: Oct | AN3: Nov | AO3: Dec | AP3: 2026 Totals
A4: JSX Heavy Inspection | D4: 1 | E4: 1 | F4: 1 | G4: 1 | H4: 1 | I4: 1 | J4: 1 | K4: 1 | L4: 1 | M4: 1 | N4: 1 | O4: 1 | P4: =SUM(D4:O4) -> 12 | Q4: 1 | R4: 1 | S4: 1 | T4: 1 | U4: 1 | W4: 1 | X4: 1 | Y4: 1 | Z4: 1 | AA4: 1 | AC4: =SUM(Q4:AB4) -> 10 | AD4: 1 | AE4: 1 | AF4: 1 | AG4: 1 | AH4: 1 | AI4: 1 | AJ4: 1 | AK4: 1 | AL4: 1 | AM4: 1 | AN4: 1 | AO4: 1 | AP4: =SUM(AD4:AO4) -> 12
A5: JSX Line Check | D5: 24 | E5: 36 | F5: 48 | G5: 60 | H5: 60 | I5: 60 | J5: 72 | K5: 72 | L5: 84 | M5: 84 | N5: 84 | O5: 84 | P5: =SUM(D5:O5) -> 768 | Q5: 84 | R5: 84 | S5: 84 | T5: 84 | U5: 84 | V5: 84 | W5: 84 | X5: 84 | Y5: 84 | Z5: 84 | AA5: 84 | AB5: 84 | AC5: =SUM(Q5:AB5) -> 1008 | AD5: 84 | AE5: 84 | AF5: 84 | AG5: 84 | AH5: 84 | AI5: 84 | AJ5: 84 | AK5: 84 | AL5: 84 | AM5: 84 | AN5: 84 | AO5: 84 | AP5: =SUM(AD5:AO5) -> 1008
A6: JSX First Flight of the day | D6: 2 | E6: 3 | F6: 4 | G6: 5 | H6: 5 | I6: 5 | J6: 6 | K6: 6 | L6: 7 | M6: 7 | N6: 7 | O6: 7 | P6: =SUM(D6:O6) -> 64 | Q6: 7 | R6: 7 | S6: 7 | T6: 7 | U6: 7 | V6: 7 | W6: 7 | X6: 7 | Y6: 7 | Z6: 7 | AA6: 7 | AB6: 7 | AC6: =SUM(Q6:AB6) -> 84 | AD6: 7 | AE6: 7 | AF6: 7 | AG6: 7 | AH6: 7 | AI6: 7 | AJ6: 7 | AK6: 7 | AL6: 7 | AM6: 7 | AN6: 7 | AO6: 7 | AP6: =SUM(AD6:AO6) -> 84
A7: JSX AOG MX | D7: 2 | E7: 3 | F7: 4 | G7: 5 | H7: 5 | I7: 5 | J7: 6 | K7: 6 | L7: 7 | M7: 7 | N7: 7 | O7: 7 | P7: =SUM(D7:O7) -> 64 | Q7: 7 | R7: 7 | S7: 7 | T7: 7 | U7: 7 | V7: 7 | W7: 7 | X7: 7 | Y7: 7 | Z7: 7 | AA7: 7 | AB7: 7 | AC7: =SUM(Q7:AB7) -> 84 | AD7: 7 | AE7: 7 | AF7: 7 | AG7: 7 | AH7: 7 | AI7: 7 | AJ7: 7 | AK7: 7 | AL7: 7 | AM7: 7 | AN7: 7 | AO7: 7 | AP7: =SUM(AD7:AO7) -> 84
A8: Retail MX | P8: =SUM(D8:O8) -> 0 | AC8: =SUM(Q8:AB8) -> 0 | AP8: =SUM(AD8:AO8) -> 0
A9: Retail AOG | P9: =SUM(D9:O9) -> 0 | AC9: =SUM(Q9:AB9) -> 0 | AP9: =SUM(AD9:AO9) -> 0
A10: Placeholder | P10: =SUM(D10:O10) -> 0 | AC10: =SUM(Q10:AB10) -> 0 | AP10: =SUM(AD10:AO10) -> 0
A11: Placeholder | P11: =SUM(D11:O11) -> 0 | AC11: =SUM(Q11:AB11) -> 0 | AP11: =SUM(AD11:AO11) -> 0
A12: Placeholder | P12: =SUM(D12:O12) -> 0 | AC12: =SUM(Q12:AB12) -> 0 | AP12: =SUM(AD12:AO12) -> 0
A14: Total Aircraft | D14: =SUM(D4:D12) -> 29 | E14: =SUM(E4:E12) -> 43 | F14: =SUM(F4:F12) -> 57 | G14: =SUM(G4:G12) -> 71 | H14: =SUM(H4:H12) -> 71 | I14: =SUM(I4:I12) -> 71 | J14: =SUM(J4:J12) -> 85 | K14: =SUM(K4:K12) -> 85 | ... O14: =SUM(O4:O12) -> 99 | P14: =SUM(D14:O14) -> 908 | Q14: =SUM(Q4:Q12) -> 99 | R14: =SUM(R4:R12) -> 99 | S14: =SUM(S4:S12) -> 99 | T14: =SUM(T4:T12) -> 99 | U14: =SUM(U4:U12) -> 99 | V14: =SUM(V4:V12) -> 98 | W14: =SUM(W4:W12) -> 99 | X14: =SUM(X4:X12) -> 99 | ... AO14: =SUM(AO4:AO12) -> 99 | AP14: =SUM(AD14:AO14) -> 1188
A15: Hangar Capacity | B15: 2
A16: Total hangar bays unused | D16: =$B$15-D14 -> -27 | E16: =$B$15-E14 -> -41 | F16: =$B$15-F14 -> -55 | G16: =$B$15-G14 -> -69 | H16: =$B$15-H14 -> -69 | I16: =$B$15-I14 -> -69 | J16: =$B$15-J14 -> -83 | K16: =$B$15-K14 -> -83 | ... O16: =$B$15-O14 -> -97 | Q16: =$B$15-Q14 -> -97 | R16: =$B$15-R14 -> -97 | S16: =$B$15-S14 -> -97 | T16: =$B$15-T14 -> -97 | U16: =$B$15-U14 -> -97 | V16: =$B$15-V14 -> -96 | W16: =$B$15-W14 -> -97 | X16: =$B$15-X14 -> -97 | ... AB16: =$B$15-AB14 -> -96 | AD16: =$B$15-AD14 -> -97 | AE16: =$B$15-AE14 -> -97 | AF16: =$B$15-AF14 -> -97 | AG16: =$B$15-AG14 -> -97 | AH16: =$B$15-AH14 -> -97 | AI16: =$B$15-AI14 -> -97 | AJ16: =$B$15-AJ14 -> -97 | AK16: =$B$15-AK14 -> -97 | ... AO16: =$B$15-AO14 -> -97
A18: Hours per month
B19: INSP Hours | C19: Repair Hours | D19: Jan | E19: Feb | F19: Mar | G19: Apr | H19: May | I19: Jun | J19: Jul | K19: Aug | L19: Sep | M19: Oct | N19: Nov | O19: Dec | Q19: Jan | R19: Feb | S19: Mar | T19: Apr | U19: May | V19: Jun | W19: Jul | X19: Aug | Y19: Sep | Z19: Oct | AA19: Nov | AB19: Dec | AD19: Jan | AE19: Feb | AF19: Mar | AG19: Apr | AH19: May | AI19: Jun | AJ19: Jul | AK19: Aug | AL19: Sep | AM19: Oct | AN19: Nov | AO19: Dec
A20: JSX Heavy Inspection | B20: 2500 | C20: 500 | D20: =(D4*$B20)+(D4*$C20) -> 3000 | E20: =(E4*$B20)+(E4*$C20) -> 3000 | F20: =(F4*$B20)+(F4*$C20) -> 3000 | G20: =(G4*$B20)+(G4*$C20) -> 3000 | H20: =(H4*$B20)+(H4*$C20) -> 3000 | I20: =(I4*$B20)+(I4*$C20) -> 3000 | J20: =(J4*$B20)+(J4*$C20) -> 3000 | K20: =(K4*$B20)+(K4*$C20) -> 3000 | ... O20: =(O4*$B20)+(O4*$C20) -> 3000 | P20: =SUM(D20:O20) -> 36000 | Q20: =(Q4*$B20)+(Q4*$C20) -> 3000 | R20: =(R4*$B20)+(R4*$C20) -> 3000 | S20: =(S4*$B20)+(S4*$C20) -> 3000 | T20: =(T4*$B20)+(T4*$C20) -> 3000 | U20: =(U4*$B20)+(U4*$C20) -> 3000 | V20: =(V4*$B20)+(V4*$C20) -> 0 | W20: =(W4*$B20)+(W4*$C20) -> 3000 | X20: =(X4*$B20)+(X4*$C20) -> 3000 | ... AB20: =(AB4*$B20)+(AB4*$C20) -> 0 | AC20: =SUM(Q20:AB20) -> 30000 | AD20: =(AD4*$B20)+(AD4*$C20) -> 3000 | AE20: =(AE4*$B20)+(AE4*$C20) -> 3000 | AF20: =(AF4*$B20)+(AF4*$C20) -> 3000 | AG20: =(AG4*$B20)+(AG4*$C20) -> 3000 | AH20: =(AH4*$B20)+(AH4*$C20) -> 3000 | AI20: =(AI4*$B20)+(AI4*$C20) -> 3000 | AJ20: =(AJ4*$B20)+(AJ4*$C20) -> 3000 | AK20: =(AK4*$B20)+(AK4*$C20) -> 3000 | ... AO20: =(AO4*$B20)+(AO4*$C20) -> 3000 | AP20: =SUM(AD20:AO20) -> 36000
A21: JSX Line Check | B21: 2 | D21: =(D5*$B21)+(D5*$C21) -> 48 | E21: =(E5*$B21)+(E5*$C21) -> 72 | F21: =(F5*$B21)+(F5*$C21) -> 96 | G21: =(G5*$B21)+(G5*$C21) -> 120 | H21: =(H5*$B21)+(H5*$C21) -> 120 | I21: =(I5*$B21)+(I5*$C21) -> 120 | J21: =(J5*$B21)+(J5*$C21) -> 144 | K21: =(K5*$B21)+(K5*$C21) -> 144 | ... O21: =(O5*$B21)+(O5*$C21) -> 168 | P21: =SUM(D21:O21) -> 1536 | Q21: =(Q5*$B21)+(Q5*$C21) -> 168 | R21: =(R5*$B21)+(R5*$C21) -> 168 | S21: =(S5*$B21)+(S5*$C21) -> 168 | T21: =(T5*$B21)+(T5*$C21) -> 168 | U21: =(U5*$B21)+(U5*$C21) -> 168 | V21: =(V5*$B21)+(V5*$C21) -> 168 | W21: =(W5*$B21)+(W5*$C21) -> 168 | X21: =(X5*$B21)+(X5*$C21) -> 168 | ... AB21: =(AB5*$B21)+(AB5*$C21) -> 168 | AC21: =SUM(Q21:AB21) -> 2016 | AD21: =(AD5*$B21)+(AD5*$C21) -> 168 | AE21: =(AE5*$B21)+(AE5*$C21) -> 168 | AF21: =(AF5*$B21)+(AF5*$C21) -> 168 | AG21: =(AG5*$B21)+(AG5*$C21) -> 168 | AH21: =(AH5*$B21)+(AH5*$C21) -> 168 | AI21: =(AI5*$B21)+(AI5*$C21) -> 168 | AJ21: =(AJ5*$B21)+(AJ5*$C21) -> 168 | AK21: =(AK5*$B21)+(AK5*$C21) -> 168 | ... AO21: =(AO5*$B21)+(AO5*$C21) -> 168 | AP21: =SUM(AD21:AO21) -> 2016
A22: JSX First Flight of the day | B22: 1.5 | D22: =(D6*$B22)+(D6*$C22) -> 3 | E22: =(E6*$B22)+(E6*$C22) -> 4.5 | F22: =(F6*$B22)+(F6*$C22) -> 6 | G22: =(G6*$B22)+(G6*$C22) -> 7.5 | H22: =(H6*$B22)+(H6*$C22) -> 7.5 | I22: =(I6*$B22)+(I6*$C22) -> 7.5 | J22: =(J6*$B22)+(J6*$C22) -> 9 | K22: =(K6*$B22)+(K6*$C22) -> 9 | ... O22: =(O6*$B22)+(O6*$C22) -> 10.5 | P22: =SUM(D22:O22) -> 96 | Q22: =(Q6*$B22)+(Q6*$C22) -> 10.5 | R22: =(R6*$B22)+(R6*$C22) -> 10.5 | S22: =(S6*$B22)+(S6*$C22) -> 10.5 | T22: =(T6*$B22)+(T6*$C22) -> 10.5 | U22: =(U6*$B22)+(U6*$C22) -> 10.5 | V22: =(V6*$B22)+(V6*$C22) -> 10.5 | W22: =(W6*$B22)+(W6*$C22) -> 10.5 | X22: =(X6*$B22)+(X6*$C22) -> 10.5 | ... AB22: =(AB6*$B22)+(AB6*$C22) -> 10.5 | AC22: =SUM(Q22:AB22) -> 126 | AD22: =(AD6*$B22)+(AD6*$C22) -> 10.5 | AE22: =(AE6*$B22)+(AE6*$C22) -> 10.5 | AF22: =(AF6*$B22)+(AF6*$C22) -> 10.5 | AG22: =(AG6*$B22)+(AG6*$C22) -> 10.5 | AH22: =(AH6*$B22)+(AH6*$C22) -> 10.5 | AI22: =(AI6*$B22)+(AI6*$C22) -> 10.5 | AJ22: =(AJ6*$B22)+(AJ6*$C22) -> 10.5 | AK22: =(AK6*$B22)+(AK6*$C22) -> 10.5 | ... AO22: =(AO6*$B22)+(AO6*$C22) -> 10.5 | AP22: =SUM(AD22:AO22) -> 126
A23: JSX AOG MX | B23: 10 | D23: =(D7*$B23)+(D7*$C23) -> 20 | E23: =(E7*$B23)+(E7*$C23) -> 30 | F23: =(F7*$B23)+(F7*$C23) -> 40 | G23: =(G7*$B23)+(G7*$C23) -> 50 | H23: =(H7*$B23)+(H7*$C23) -> 50 | I23: =(I7*$B23)+(I7*$C23) -> 50 | J23: =(J7*$B23)+(J7*$C23) -> 60 | K23: =(K7*$B23)+(K7*$C23) -> 60 | ... O23: =(O7*$B23)+(O7*$C23) -> 70 | P23: =SUM(D23:O23) -> 640 | Q23: =(Q7*$B23)+(Q7*$C23) -> 70 | R23: =(R7*$B23)+(R7*$C23) -> 70 | S23: =(S7*$B23)+(S7*$C23) -> 70 | T23: =(T7*$B23)+(T7*$C23) -> 70 | U23: =(U7*$B23)+(U7*$C23) -> 70 | V23: =(V7*$B23)+(V7*$C23) -> 70 | W23: =(W7*$B23)+(W7*$C23) -> 70 | X23: =(X7*$B23)+(X7*$C23) -> 70 | ... AB23: =(AB7*$B23)+(AB7*$C23) -> 70 | AC23: =SUM(Q23:AB23) -> 840 | AD23: =(AD7*$B23)+(AD7*$C23) -> 70 | AE23: =(AE7*$B23)+(AE7*$C23) -> 70 | AF23: =(AF7*$B23)+(AF7*$C23) -> 70 | AG23: =(AG7*$B23)+(AG7*$C23) -> 70 | AH23: =(AH7*$B23)+(AH7*$C23) -> 70 | AI23: =(AI7*$B23)+(AI7*$C23) -> 70 | AJ23: =(AJ7*$B23)+(AJ7*$C23) -> 70 | AK23: =(AK7*$B23)+(AK7*$C23) -> 70 | ... AO23: =(AO7*$B23)+(AO7*$C23) -> 70 | AP23: =SUM(AD23:AO23) -> 840
A24: Retail MX | D24: =(D8*$B24)+(D8*$C24) -> 0 | E24: =(E8*$B24)+(E8*$C24) -> 0 | F24: =(F8*$B24)+(F8*$C24) -> 0 | G24: =(G8*$B24)+(G8*$C24) -> 0 | H24: =(H8*$B24)+(H8*$C24) -> 0 | I24: =(I8*$B24)+(I8*$C24) -> 0 | J24: =(J8*$B24)+(J8*$C24) -> 0 | K24: =(K8*$B24)+(K8*$C24) -> 0 | ... O24: =(O8*$B24)+(O8*$C24) -> 0 | P24: =SUM(D24:O24) -> 0 | Q24: =(Q8*$B24)+(Q8*$C24) -> 0 | R24: =(R8*$B24)+(R8*$C24) -> 0 | S24: =(S8*$B24)+(S8*$C24) -> 0 | T24: =(T8*$B24)+(T8*$C24) -> 0 | U24: =(U8*$B24)+(U8*$C24) -> 0 | V24: =(V8*$B24)+(V8*$C24) -> 0 | W24: =(W8*$B24)+(W8*$C24) -> 0 | X24: =(X8*$B24)+(X8*$C24) -> 0 | ... AB24: =(AB8*$B24)+(AB8*$C24) -> 0 | AC24: =SUM(Q24:AB24) -> 0 | AD24: =(AD8*$B24)+(AD8*$C24) -> 0 | AE24: =(AE8*$B24)+(AE8*$C24) -> 0 | AF24: =(AF8*$B24)+(AF8*$C24) -> 0 | AG24: =(AG8*$B24)+(AG8*$C24) -> 0 | AH24: =(AH8*$B24)+(AH8*$C24) -> 0 | AI24: =(AI8*$B24)+(AI8*$C24) -> 0 | AJ24: =(AJ8*$B24)+(AJ8*$C24) -> 0 | AK24: =(AK8*$B24)+(AK8*$C24) -> 0 | ... AO24: =(AO8*$B24)+(AO8*$C24) -> 0 | AP24: =SUM(AD24:AO24) -> 0
A25: Retail AOG | D25: =(D9*$B25)+(D9*$C25) -> 0 | E25: =(E9*$B25)+(E9*$C25) -> 0 | F25: =(F9*$B25)+(F9*$C25) -> 0 | G25: =(G9*$B25)+(G9*$C25) -> 0 | H25: =(H9*$B25)+(H9*$C25) -> 0 | I25: =(I9*$B25)+(I9*$C25) -> 0 | J25: =(J9*$B25)+(J9*$C25) -> 0 | K25: =(K9*$B25)+(K9*$C25) -> 0 | ... O25: =(O9*$B25)+(O9*$C25) -> 0 | P25: =SUM(D25:O25) -> 0 | Q25: =(Q9*$B25)+(Q9*$C25) -> 0 | R25: =(R9*$B25)+(R9*$C25) -> 0 | S25: =(S9*$B25)+(S9*$C25) -> 0 | T25: =(T9*$B25)+(T9*$C25) -> 0 | U25: =(U9*$B25)+(U9*$C25) -> 0 | V25: =(V9*$B25)+(V9*$C25) -> 0 | W25: =(W9*$B25)+(W9*$C25) -> 0 | X25: =(X9*$B25)+(X9*$C25) -> 0 | ... AB25: =(AB9*$B25)+(AB9*$C25) -> 0 | AC25: =SUM(Q25:AB25) -> 0 | AD25: =(AD9*$B25)+(AD9*$C25) -> 0 | AE25: =(AE9*$B25)+(AE9*$C25) -> 0 | AF25: =(AF9*$B25)+(AF9*$C25) -> 0 | AG25: =(AG9*$B25)+(AG9*$C25) -> 0 | AH25: =(AH9*$B25)+(AH9*$C25) -> 0 | AI25: =(AI9*$B25)+(AI9*$C25) -> 0 | AJ25: =(AJ9*$B25)+(AJ9*$C25) -> 0 | AK25: =(AK9*$B25)+(AK9*$C25) -> 0 | ... AO25: =(AO9*$B25)+(AO9*$C25) -> 0 | AP25: =SUM(AD25:AO25) -> 0
A26: Placeholder | D26: =(D10*$B26)+(D10*$C26) -> 0 | E26: =(E10*$B26)+(E10*$C26) -> 0 | F26: =(F10*$B26)+(F10*$C26) -> 0 | G26: =(G10*$B26)+(G10*$C26) -> 0 | H26: =(H10*$B26)+(H10*$C26) -> 0 | I26: =(I10*$B26)+(I10*$C26) -> 0 | J26: =(J10*$B26)+(J10*$C26) -> 0 | K26: =(K10*$B26)+(K10*$C26) -> 0 | ... O26: =(O10*$B26)+(O10*$C26) -> 0 | P26: =SUM(D26:O26) -> 0 | Q26: =(Q10*$B26)+(Q10*$C26) -> 0 | R26: =(R10*$B26)+(R10*$C26) -> 0 | S26: =(S10*$B26)+(S10*$C26) -> 0 | T26: =(T10*$B26)+(T10*$C26) -> 0 | U26: =(U10*$B26)+(U10*$C26) -> 0 | V26: =(V10*$B26)+(V10*$C26) -> 0 | W26: =(W10*$B26)+(W10*$C26) -> 0 | X26: =(X10*$B26)+(X10*$C26) -> 0 | ... AB26: =(AB10*$B26)+(AB10*$C26) -> 0 | AC26: =SUM(Q26:AB26) -> 0 | AD26: =(AD10*$B26)+(AD10*$C26) -> 0 | AE26: =(AE10*$B26)+(AE10*$C26) -> 0 | AF26: =(AF10*$B26)+(AF10*$C26) -> 0 | AG26: =(AG10*$B26)+(AG10*$C26) -> 0 | AH26: =(AH10*$B26)+(AH10*$C26) -> 0 | AI26: =(AI10*$B26)+(AI10*$C26) -> 0 | AJ26: =(AJ10*$B26)+(AJ10*$C26) -> 0 | AK26: =(AK10*$B26)+(AK10*$C26) -> 0 | ... AO26: =(AO10*$B26)+(AO10*$C26) -> 0 | AP26: =SUM(AD26:AO26) -> 0
A27: Placeholder | D27: =(D11*$B27)+(D11*$C27) -> 0 | E27: =(E11*$B27)+(E11*$C27) -> 0 | F27: =(F11*$B27)+(F11*$C27) -> 0 | G27: =(G11*$B27)+(G11*$C27) -> 0 | H27: =(H11*$B27)+(H11*$C27) -> 0 | I27: =(I11*$B27)+(I11*$C27) -> 0 | J27: =(J11*$B27)+(J11*$C27) -> 0 | K27: =(K11*$B27)+(K11*$C27) -> 0 | ... O27: =(O11*$B27)+(O11*$C27) -> 0 | P27: =SUM(D27:O27) -> 0 | Q27: =(Q11*$B27)+(Q11*$C27) -> 0 | R27: =(R11*$B27)+(R11*$C27) -> 0 | S27: =(S11*$B27)+(S11*$C27) -> 0 | T27: =(T11*$B27)+(T11*$C27) -> 0 | U27: =(U11*$B27)+(U11*$C27) -> 0 | V27: =(V11*$B27)+(V11*$C27) -> 0 | W27: =(W11*$B27)+(W11*$C27) -> 0 | X27: =(X11*$B27)+(X11*$C27) -> 0 | ... AB27: =(AB11*$B27)+(AB11*$C27) -> 0 | AC27: =SUM(Q27:AB27) -> 0 | AD27: =(AD11*$B27)+(AD11*$C27) -> 0 | AE27: =(AE11*$B27)+(AE11*$C27) -> 0 | AF27: =(AF11*$B27)+(AF11*$C27) -> 0 | AG27: =(AG11*$B27)+(AG11*$C27) -> 0 | AH27: =(AH11*$B27)+(AH11*$C27) -> 0 | AI27: =(AI11*$B27)+(AI11*$C27) -> 0 | AJ27: =(AJ11*$B27)+(AJ11*$C27) -> 0 | AK27: =(AK11*$B27)+(AK11*$C27) -> 0 | ... AO27: =(AO11*$B27)+(AO11*$C27) -> 0 | AP27: =SUM(AD27:AO27) -> 0
A28: Placeholder | D28: =(D12*$B28)+(D12*$C28) -> 0 | E28: =(E12*$B28)+(E12*$C28) -> 0 | F28: =(F12*$B28)+(F12*$C28) -> 0 | G28: =(G12*$B28)+(G12*$C28) -> 0 | H28: =(H12*$B28)+(H12*$C28) -> 0 | I28: =(I12*$B28)+(I12*$C28) -> 0 | J28: =(J12*$B28)+(J12*$C28) -> 0 | K28: =(K12*$B28)+(K12*$C28) -> 0 | ... O28: =(O12*$B28)+(O12*$C28) -> 0 | P28: =SUM(D28:O28) -> 0 | Q28: =(Q12*$B28)+(Q12*$C28) -> 0 | R28: =(R12*$B28)+(R12*$C28) -> 0 | S28: =(S12*$B28)+(S12*$C28) -> 0 | T28: =(T12*$B28)+(T12*$C28) -> 0 | U28: =(U12*$B28)+(U12*$C28) -> 0 | V28: =(V12*$B28)+(V12*$C28) -> 0 | W28: =(W12*$B28)+(W12*$C28) -> 0 | X28: =(X12*$B28)+(X12*$C28) -> 0 | ... AB28: =(AB12*$B28)+(AB12*$C28) -> 0 | AC28: =SUM(Q28:AB28) -> 0 | AD28: =(AD12*$B28)+(AD12*$C28) -> 0 | AE28: =(AE12*$B28)+(AE12*$C28) -> 0 | AF28: =(AF12*$B28)+(AF12*$C28) -> 0 | AG28: =(AG12*$B28)+(AG12*$C28) -> 0 | AH28: =(AH12*$B28)+(AH12*$C28) -> 0 | AI28: =(AI12*$B28)+(AI12*$C28) -> 0 | AJ28: =(AJ12*$B28)+(AJ12*$C28) -> 0 | AK28: =(AK12*$B28)+(AK12*$C28) -> 0 | ... AO28: =(AO12*$B28)+(AO12*$C28) -> 0 | AP28: =SUM(AD28:AO28) -> 0
A29: Total Hours | D29: =SUM(D20:D28) -> 3071 | E29: =SUM(E20:E28) -> 3106.5 | F29: =SUM(F20:F28) -> 3142 | G29: =SUM(G20:G28) -> 3177.5 | H29: =SUM(H20:H28) -> 3177.5 | I29: =SUM(I20:I28) -> 3177.5 | J29: =SUM(J20:J28) -> 3213 | K29: =SUM(K20:K28) -> 3213 | ... AP29: =SUM(AP20:AP28) -> 38982
P30: =SUM(D30:O30) -> 0 | AC30: =SUM(Q30:AB30) -> 0 | AP30: =SUM(AD30:AO30) -> 0
A31: Labor Rates
A32: JSX Heavy Inspection | B32: 100 | D32: =D20*$B$32 -> 300000 | E32: =E20*$B$32 -> 300000 | F32: =F20*$B$32 -> 300000 | G32: =G20*$B$32 -> 300000 | H32: =H20*$B$32 -> 300000 | I32: =I20*$B$32 -> 300000 | J32: =J20*$B$32 -> 300000 | K32: =K20*$B$32 -> 300000 | ... O32: =O20*$B$32 -> 300000 | P32: =SUM(D32:O32) -> 3600000 | Q32: =Q20*$B$32 -> 300000 | R32: =R20*$B$32 -> 300000 | S32: =S20*$B$32 -> 300000 | T32: =T20*$B$32 -> 300000 | U32: =U20*$B$32 -> 300000 | V32: =V20*$B$32 -> 0 | W32: =W20*$B$32 -> 300000 | X32: =X20*$B$32 -> 300000 | ... AB32: =AB20*$B$32 -> 0 | AC32: =SUM(Q32:AB32) -> 3000000 | AD32: =AD20*$B$32 -> 300000 | AE32: =AE20*$B$32 -> 300000 | AF32: =AF20*$B$32 -> 300000 | AG32: =AG20*$B$32 -> 300000 | AH32: =AH20*$B$32 -> 300000 | AI32: =AI20*$B$32 -> 300000 | AJ32: =AJ20*$B$32 -> 300000 | AK32: =AK20*$B$32 -> 300000 | ... AO32: =AO20*$B$32 -> 300000 | AP32: =SUM(AD32:AO32) -> 3600000
A33: JSX Line Check | B33: 500 | D33: =D21*$B$32 -> 4800 | E33: =E21*$B$32 -> 7200 | F33: =F21*$B$32 -> 9600 | G33: =G21*$B$32 -> 12000 | H33: =H21*$B$32 -> 12000 | I33: =I21*$B$32 -> 12000 | J33: =J21*$B$32 -> 14400 | K33: =K21*$B$32 -> 14400 | ... O33: =O21*$B$32 -> 16800 | P33: =SUM(D33:O33) -> 153600 | Q33: =Q21*$B$32 -> 16800 | R33: =R21*$B$32 -> 16800 | S33: =S21*$B$32 -> 16800 | T33: =T21*$B$32 -> 16800 | U33: =U21*$B$32 -> 16800 | V33: =V21*$B$32 -> 16800 | W33: =W21*$B$32 -> 16800 | X33: =X21*$B$32 -> 16800 | ... AB33: =AB21*$B$32 -> 16800 | AC33: =SUM(Q33:AB33) -> 201600 | AD33: =AD21*$B$32 -> 16800 | AE33: =AE21*$B$32 -> 16800 | AF33: =AF21*$B$32 -> 16800 | AG33: =AG21*$B$32 -> 16800 | AH33: =AH21*$B$32 -> 16800 | AI33: =AI21*$B$32 -> 16800 | AJ33: =AJ21*$B$32 -> 16800 | AK33: =AK21*$B$32 -> 16800 | ... AO33: =AO21*$B$32 -> 16800 | AP33: =SUM(AD33:AO33) -> 201600
A34: JSX First Flight of the day | B34: 130 | D34: =D22*$B$32 -> 300 | E34: =E22*$B$32 -> 450 | F34: =F22*$B$32 -> 600 | G34: =G22*$B$32 -> 750 | H34: =H22*$B$32 -> 750 | I34: =I22*$B$32 -> 750 | J34: =J22*$B$32 -> 900 | K34: =K22*$B$32 -> 900 | ... O34: =O22*$B$32 -> 1050 | Q34: =Q22*$B$32 -> 1050 | R34: =R22*$B$32 -> 1050 | S34: =S22*$B$32 -> 1050 | T34: =T22*$B$32 -> 1050 | U34: =U22*$B$32 -> 1050 | V34: =V22*$B$32 -> 1050 | W34: =W22*$B$32 -> 1050 | X34: =X22*$B$32 -> 1050 | ... AB34: =AB22*$B$32 -> 1050 | AD34: =AD22*$B$32 -> 1050 | AE34: =AE22*$B$32 -> 1050 | AF34: =AF22*$B$32 -> 1050 | AG34: =AG22*$B$32 -> 1050 | AH34: =AH22*$B$32 -> 1050 | AI34: =AI22*$B$32 -> 1050 | AJ34: =AJ22*$B$32 -> 1050 | AK34: =AK22*$B$32 -> 1050 | ... AO34: =AO22*$B$32 -> 1050
A35: JSX AOG MX | B35: 195 | D35: =D23*$B$32 -> 2000 | E35: =E23*$B$32 -> 3000 | F35: =F23*$B$32 -> 4000 | G35: =G23*$B$32 -> 5000 | H35: =H23*$B$32 -> 5000 | I35: =I23*$B$32 -> 5000 | J35: =J23*$B$32 -> 6000 | K35: =K23*$B$32 -> 6000 | ... O35: =O23*$B$32 -> 7000 | Q35: =Q23*$B$32 -> 7000 | R35: =R23*$B$32 -> 7000 | S35: =S23*$B$32 -> 7000 | T35: =T23*$B$32 -> 7000 | U35: =U23*$B$32 -> 7000 | V35: =V23*$B$32 -> 7000 | W35: =W23*$B$32 -> 7000 | X35: =X23*$B$32 -> 7000 | ... AB35: =AB23*$B$32 -> 7000 | AD35: =AD23*$B$32 -> 7000 | AE35: =AE23*$B$32 -> 7000 | AF35: =AF23*$B$32 -> 7000 | AG35: =AG23*$B$32 -> 7000 | AH35: =AH23*$B$32 -> 7000 | AI35: =AI23*$B$32 -> 7000 | AJ35: =AJ23*$B$32 -> 7000 | AK35: =AK23*$B$32 -> 7000 | ... AO35: =AO23*$B$32 -> 7000
A36: Retail MX | B36: 169 | D36: =D24*$B$32 -> 0 | E36: =E24*$B$32 -> 0 | F36: =F24*$B$32 -> 0 | G36: =G24*$B$32 -> 0 | H36: =H24*$B$32 -> 0 | I36: =I24*$B$32 -> 0 | J36: =J24*$B$32 -> 0 | K36: =K24*$B$32 -> 0 | ... O36: =O24*$B$32 -> 0 | Q36: =Q24*$B$32 -> 0 | R36: =R24*$B$32 -> 0 | S36: =S24*$B$32 -> 0 | T36: =T24*$B$32 -> 0 | U36: =U24*$B$32 -> 0 | V36: =V24*$B$32 -> 0 | W36: =W24*$B$32 -> 0 | X36: =X24*$B$32 -> 0 | ... AB36: =AB24*$B$32 -> 0 | AD36: =AD24*$B$32 -> 0 | AE36: =AE24*$B$32 -> 0 | AF36: =AF24*$B$32 -> 0 | AG36: =AG24*$B$32 -> 0 | AH36: =AH24*$B$32 -> 0 | AI36: =AI24*$B$32 -> 0 | AJ36: =AJ24*$B$32 -> 0 | AK36: =AK24*$B$32 -> 0 | ... AO36: =AO24*$B$32 -> 0
A37: Retail AOG | B37: 254 | D37: =D25*$B$32 -> 0 | E37: =E25*$B$32 -> 0 | F37: =F25*$B$32 -> 0 | G37: =G25*$B$32 -> 0 | H37: =H25*$B$32 -> 0 | I37: =I25*$B$32 -> 0 | J37: =J25*$B$32 -> 0 | K37: =K25*$B$32 -> 0 | ... O37: =O25*$B$32 -> 0 | Q37: =Q25*$B$32 -> 0 | R37: =R25*$B$32 -> 0 | S37: =S25*$B$32 -> 0 | T37: =T25*$B$32 -> 0 | U37: =U25*$B$32 -> 0 | V37: =V25*$B$32 -> 0 | W37: =W25*$B$32 -> 0 | X37: =X25*$B$32 -> 0 | ... AB37: =AB25*$B$32 -> 0 | AD37: =AD25*$B$32 -> 0 | AE37: =AE25*$B$32 -> 0 | AF37: =AF25*$B$32 -> 0 | AG37: =AG25*$B$32 -> 0 | AH37: =AH25*$B$32 -> 0 | AI37: =AI25*$B$32 -> 0 | AJ37: =AJ25*$B$32 -> 0 | AK37: =AK25*$B$32 -> 0 | ... AO37: =AO25*$B$32 -> 0
A38: Placeholder | D38: =D26*$B$32 -> 0 | E38: =E26*$B$32 -> 0 | F38: =F26*$B$32 -> 0 | G38: =G26*$B$32 -> 0 | H38: =H26*$B$32 -> 0 | I38: =I26*$B$32 -> 0 | J38: =J26*$B$32 -> 0 | K38: =K26*$B$32 -> 0 | ... O38: =O26*$B$32 -> 0 | Q38: =Q26*$B$32 -> 0 | R38: =R26*$B$32 -> 0 | S38: =S26*$B$32 -> 0 | T38: =T26*$B$32 -> 0 | U38: =U26*$B$32 -> 0 | V38: =V26*$B$32 -> 0 | W38: =W26*$B$32 -> 0 | X38: =X26*$B$32 -> 0 | ... AB38: =AB26*$B$32 -> 0 | AD38: =AD26*$B$32 -> 0 | AE38: =AE26*$B$32 -> 0 | AF38: =AF26*$B$32 -> 0 | AG38: =AG26*$B$32 -> 0 | AH38: =AH26*$B$32 -> 0 | AI38: =AI26*$B$32 -> 0 | AJ38: =AJ26*$B$32 -> 0 | AK38: =AK26*$B$32 -> 0 | ... AO38: =AO26*$B$32 -> 0
A39: Placeholder | D39: =D27*$B$32 -> 0 | E39: =E27*$B$32 -> 0 | F39: =F27*$B$32 -> 0 | G39: =G27*$B$32 -> 0 | H39: =H27*$B$32 -> 0 | I39: =I27*$B$32 -> 0 | J39: =J27*$B$32 -> 0 | K39: =K27*$B$32 -> 0 | ... O39: =O27*$B$32 -> 0 | Q39: =Q27*$B$32 -> 0 | R39: =R27*$B$32 -> 0 | S39: =S27*$B$32 -> 0 | T39: =T27*$B$32 -> 0 | U39: =U27*$B$32 -> 0 | V39: =V27*$B$32 -> 0 | W39: =W27*$B$32 -> 0 | X39: =X27*$B$32 -> 0 | ... AB39: =AB27*$B$32 -> 0 | AD39: =AD27*$B$32 -> 0 | AE39: =AE27*$B$32 -> 0 | AF39: =AF27*$B$32 -> 0 | AG39: =AG27*$B$32 -> 0 | AH39: =AH27*$B$32 -> 0 | AI39: =AI27*$B$32 -> 0 | AJ39: =AJ27*$B$32 -> 0 | AK39: =AK27*$B$32 -> 0 | ... AO39: =AO27*$B$32 -> 0
A40: Placeholder | D40: =D28*$B$32 -> 0 | E40: =E28*$B$32 -> 0 | F40: =F28*$B$32 -> 0 | G40: =G28*$B$32 -> 0 | H40: =H28*$B$32 -> 0 | I40: =I28*$B$32 -> 0 | J40: =J28*$B$32 -> 0 | K40: =K28*$B$32 -> 0 | ... O40: =O28*$B$32 -> 0 | Q40: =Q28*$B$32 -> 0 | R40: =R28*$B$32 -> 0 | S40: =S28*$B$32 -> 0 | T40: =T28*$B$32 -> 0 | U40: =U28*$B$32 -> 0 | V40: =V28*$B$32 -> 0 | W40: =W28*$B$32 -> 0 | X40: =X28*$B$32 -> 0 | ... AB40: =AB28*$B$32 -> 0 | AD40: =AD28*$B$32 -> 0 | AE40: =AE28*$B$32 -> 0 | AF40: =AF28*$B$32 -> 0 | AG40: =AG28*$B$32 -> 0 | AH40: =AH28*$B$32 -> 0 | AI40: =AI28*$B$32 -> 0 | AJ40: =AJ28*$B$32 -> 0 | AK40: =AK28*$B$32 -> 0 | ... AO40: =AO28*$B$32 -> 0
A41: Total Revenue | D41: =SUM(D32:D40) -> 307100 | E41: =SUM(E32:E40) -> 310650 | F41: =SUM(F32:F40) -> 314200 | G41: =SUM(G32:G40) -> 317750 | H41: =SUM(H32:H40) -> 317750 | I41: =SUM(I32:I40) -> 317750 | J41: =SUM(J32:J40) -> 321300 | K41: =SUM(K32:K40) -> 321300 | ... O41: =SUM(O32:O40) -> 324850 | P41: =SUM(D41:O41) -> 3827200 | Q41: =SUM(Q32:Q40) -> 324850 | R41: =SUM(R32:R40) -> 324850 | S41: =SUM(S32:S40) -> 324850 | T41: =SUM(T32:T40) -> 324850 | U41: =SUM(U32:U40) -> 324850 | V41: =SUM(V32:V40) -> 24850 | W41: =SUM(W32:W40) -> 324850 | X41: =SUM(X32:X40) -> 324850 | ... AB41: =SUM(AB32:AB40) -> 24850 | AC41: =SUM(Q41:AB41) -> 3298200 | AD41: =SUM(AD32:AD40) -> 324850 | AE41: =SUM(AE32:AE40) -> 324850 | AF41: =SUM(AF32:AF40) -> 324850 | AG41: =SUM(AG32:AG40) -> 324850 | AH41: =SUM(AH32:AH40) -> 324850 | AI41: =SUM(AI32:AI40) -> 324850 | AJ41: =SUM(AJ32:AJ40) -> 324850 | AK41: =SUM(AK32:AK40) -> 324850 | ... AO41: =SUM(AO32:AO40) -> 324850 | AP41: =SUM(AD41:AO41) -> 3898200
A43: Effective Techs | D43: ='Man Hours & Costs'!C18 -> 20.8 | E43: ='Man Hours & Costs'!D18 -> 20.8 | F43: ='Man Hours & Costs'!E18 -> 20.8 | G43: ='Man Hours & Costs'!F18 -> 20.8 | H43: ='Man Hours & Costs'!G18 -> 20.8 | I43: ='Man Hours & Costs'!H18 -> 20.8 | J43: ='Man Hours & Costs'!I18 -> 20.8 | K43: ='Man Hours & Costs'!J18 -> 20.8 | ... O43: ='Man Hours & Costs'!N18 -> 20.8 | Q43: ='Man Hours & Costs'!P18 -> 24 | R43: ='Man Hours & Costs'!Q18 -> 28.8 | S43: ='Man Hours & Costs'!R18 -> 28.8 | T43: ='Man Hours & Costs'!S18 -> 28.8 | U43: ='Man Hours & Costs'!T18 -> 28.8 | V43: ='Man Hours & Costs'!U18 -> 28.8 | W43: ='Man Hours & Costs'!V18 -> 28.8 | X43: ='Man Hours & Costs'!W18 -> 24 | ... AB43: ='Man Hours & Costs'!AA18 -> 24 | AD43: ='Man Hours & Costs'!AC18 -> 24 | AE43: ='Man Hours & Costs'!AD18 -> 24 | AF43: ='Man Hours & Costs'!AE18 -> 24 | AG43: ='Man Hours & Costs'!AF18 -> 24 | AH43: ='Man Hours & Costs'!AG18 -> 24 | AI43: ='Man Hours & Costs'!AH18 -> 24 | AJ43: ='Man Hours & Costs'!AI18 -> 24 | AK43: ='Man Hours & Costs'!AJ18 -> 24 | ... AO43: ='Man Hours & Costs'!AN18 -> 24
...

Sheet Visualization
B116: ='2023 Forecast Totals'!D$3 -> Jan | C116: ='2023 Forecast Totals'!E$3 -> Feb | D116: ='2023 Forecast Totals'!F$3 -> Mar | E116: ='2023 Forecast Totals'!G$3 -> Apr | F116: ='2023 Forecast Totals'!H$3 -> May | G116: ='2023 Forecast Totals'!I$3 -> Jun | H116: ='2023 Forecast Totals'!J$3 -> Jul | I116: ='2023 Forecast Totals'!K$3 -> Aug | ... M116: ='2023 Forecast Totals'!O$3 -> Dec
A117: =TEAMGROWTH!D27 -> Avionics lead | B117: =TEAMGROWTH!L27 -> 164.56825 | C117: =TEAMGROWTH!N27 -> 164.56825 | D117: =TEAMGROWTH!P27 -> 164.56825 | E117: =TEAMGROWTH!R27 -> 164.56825 | F117: =TEAMGROWTH!T27 -> 164.56825 | G117: =TEAMGROWTH!V27 -> 164.56825 | H117: =TEAMGROWTH!X27 -> 164.56825 | I117: =TEAMGROWTH!Z27 -> 164.56825 | J117: =TEAMGROWTH!AB27 -> 164.56825 | K117: =TEAMGROWTH!AD27 -> 164.56825 | L117: =TEAMGROWTH!AF27 -> 164.56825 | M117: =TEAMGROWTH!AH27 -> 164.56825
A118: =TEAMGROWTH!D28 -> Lead | B118: =TEAMGROWTH!L28 -> 82.284125 | C118: =TEAMGROWTH!N28 -> 82.284125 | D118: =TEAMGROWTH!P28 -> 82.284125 | E118: =TEAMGROWTH!R28 -> 82.284125 | F118: =TEAMGROWTH!T28 -> 82.284125 | G118: =TEAMGROWTH!V28 -> 82.284125 | H118: =TEAMGROWTH!X28 -> 82.284125 | I118: =TEAMGROWTH!Z28 -> 82.284125 | J118: =TEAMGROWTH!AB28 -> 82.284125 | K118: =TEAMGROWTH!AD28 -> 82.284125 | L118: =TEAMGROWTH!AF28 -> 82.284125 | M118: =TEAMGROWTH!AH28 -> 82.284125
A119: =TEAMGROWTH!D29 -> Joe Vigil AP/AV | B119: =TEAMGROWTH!L29 -> 164.56825 | C119: =TEAMGROWTH!N29 -> 164.56825 | D119: =TEAMGROWTH!P29 -> 164.56825 | E119: =TEAMGROWTH!R29 -> 164.56825 | F119: =TEAMGROWTH!T29 -> 164.56825 | G119: =TEAMGROWTH!V29 -> 164.56825 | H119: =TEAMGROWTH!X29 -> 164.56825 | I119: =TEAMGROWTH!Z29 -> 164.56825 | J119: =TEAMGROWTH!AB29 -> 164.56825 | K119: =TEAMGROWTH!AD29 -> 164.56825 | L119: =TEAMGROWTH!AF29 -> 164.56825 | M119: =TEAMGROWTH!AH29 -> 164.56825
A120: =TEAMGROWTH!D30 -> X Mech 1, 1-3YR AP | B120: =TEAMGROWTH!L30 -> 115.19777 | C120: =TEAMGROWTH!N30 -> 143.99722 | D120: =TEAMGROWTH!P30 -> 164.56825 | E120: =TEAMGROWTH!R30 -> 164.56825 | F120: =TEAMGROWTH!T30 -> 164.56825 | G120: =TEAMGROWTH!V30 -> 164.56825 | H120: =TEAMGROWTH!X30 -> 164.56825 | I120: =TEAMGROWTH!Z30 -> 164.56825 | J120: =TEAMGROWTH!AB30 -> 164.56825 | K120: =TEAMGROWTH!AD30 -> 164.56825 | L120: =TEAMGROWTH!AF30 -> 164.56825 | M120: =TEAMGROWTH!AH30 -> 164.56825
A121: =TEAMGROWTH!D31 -> X Mech 2, 1-3YR Entry AP | B121: =TEAMGROWTH!L31 -> 115.19777 | C121: =TEAMGROWTH!N31 -> 143.99722 | D121: =TEAMGROWTH!P31 -> 164.56825 | E121: =TEAMGROWTH!R31 -> 164.56825 | F121: =TEAMGROWTH!T31 -> 164.56825 | G121: =TEAMGROWTH!V31 -> 164.56825 | H121: =TEAMGROWTH!X31 -> 164.56825 | I121: =TEAMGROWTH!Z31 -> 164.56825 | J121: =TEAMGROWTH!AB31 -> 164.56825 | K121: =TEAMGROWTH!AD31 -> 164.56825 | L121: =TEAMGROWTH!AF31 -> 164.56825 | M121: =TEAMGROWTH!AH31 -> 164.56825
A122: =TEAMGROWTH!D32 -> X Mech 3, Entry AP | B122: =TEAMGROWTH!L32 -> 115.19777 | C122: =TEAMGROWTH!N32 -> 143.99722 | D122: =TEAMGROWTH!P32 -> 164.56825 | E122: =TEAMGROWTH!R32 -> 164.56825 | F122: =TEAMGROWTH!T32 -> 164.56825 | G122: =TEAMGROWTH!V32 -> 164.56825 | H122: =TEAMGROWTH!X32 -> 164.56825 | I122: =TEAMGROWTH!Z32 -> 164.56825 | J122: =TEAMGROWTH!AB32 -> 164.56825 | K122: =TEAMGROWTH!AD32 -> 164.56825 | L122: =TEAMGROWTH!AF32 -> 164.56825 | M122: =TEAMGROWTH!AH32 -> 164.56825
A123: =TEAMGROWTH!D33 -> X Mech 4, Entry AP | B123: =TEAMGROWTH!L33 -> 98.74095 | C123: =TEAMGROWTH!N33 -> 115.19777 | D123: =TEAMGROWTH!P33 -> 143.99722 | E123: =TEAMGROWTH!R33 -> 164.56825 | F123: =TEAMGROWTH!T33 -> 164.56825 | G123: =TEAMGROWTH!V33 -> 164.56825 | H123: =TEAMGROWTH!X33 -> 164.56825 | I123: =TEAMGROWTH!Z33 -> 164.56825 | J123: =TEAMGROWTH!AB33 -> 164.56825 | K123: =TEAMGROWTH!AD33 -> 164.56825 | L123: =TEAMGROWTH!AF33 -> 164.56825 | M123: =TEAMGROWTH!AH33 -> 164.56825
A124: =TEAMGROWTH!D34 -> Detailer and line support | B124: =TEAMGROWTH!L34 -> 49.370475 | C124: =TEAMGROWTH!N34 -> 49.370475 | D124: =TEAMGROWTH!P34 -> 49.370475 | E124: =TEAMGROWTH!R34 -> 49.370475 | F124: =TEAMGROWTH!T34 -> 49.370475 | G124: =TEAMGROWTH!V34 -> 49.370475 | H124: =TEAMGROWTH!X34 -> 49.370475 | I124: =TEAMGROWTH!Z34 -> 49.370475 | J124: =TEAMGROWTH!AB34 -> 49.370475 | K124: =TEAMGROWTH!AD34 -> 49.370475 | L124: =TEAMGROWTH!AF34 -> 49.370475 | M124: =TEAMGROWTH!AH34 -> 49.370475
A125: =TEAMGROWTH!#REF! -> #REF! | B125: =TEAMGROWTH!#REF! -> #REF! | C125: =TEAMGROWTH!#REF! -> #REF! | D125: =TEAMGROWTH!#REF! -> #REF! | E125: =TEAMGROWTH!#REF! -> #REF! | F125: =TEAMGROWTH!#REF! -> #REF! | G125: =TEAMGROWTH!#REF! -> #REF! | H125: =TEAMGROWTH!#REF! -> #REF! | ... M125: =TEAMGROWTH!#REF! -> #REF!
A126: =TEAMGROWTH!#REF! -> #REF! | B126: =TEAMGROWTH!#REF! -> #REF! | C126: =TEAMGROWTH!#REF! -> #REF! | D126: =TEAMGROWTH!#REF! -> #REF! | E126: =TEAMGROWTH!#REF! -> #REF! | F126: =TEAMGROWTH!#REF! -> #REF! | G126: =TEAMGROWTH!#REF! -> #REF! | H126: =TEAMGROWTH!#REF! -> #REF! | ... M126: =TEAMGROWTH!#REF! -> #REF!
A127: =TEAMGROWTH!#REF! -> #REF! | B127: =TEAMGROWTH!#REF! -> #REF! | C127: =TEAMGROWTH!#REF! -> #REF! | D127: =TEAMGROWTH!#REF! -> #REF! | E127: =TEAMGROWTH!#REF! -> #REF! | F127: =TEAMGROWTH!#REF! -> #REF! | G127: =TEAMGROWTH!#REF! -> #REF! | H127: =TEAMGROWTH!#REF! -> #REF! | ... M127: =TEAMGROWTH!#REF! -> #REF!
A128: =TEAMGROWTH!#REF! -> #REF! | B128: =TEAMGROWTH!#REF! -> #REF! | C128: =TEAMGROWTH!#REF! -> #REF! | D128: =TEAMGROWTH!#REF! -> #REF! | E128: =TEAMGROWTH!#REF! -> #REF! | F128: =TEAMGROWTH!#REF! -> #REF! | G128: =TEAMGROWTH!#REF! -> #REF! | H128: =TEAMGROWTH!#REF! -> #REF! | ... M128: =TEAMGROWTH!#REF! -> #REF!
A129: =TEAMGROWTH!#REF! -> #REF! | B129: =TEAMGROWTH!#REF! -> #REF! | C129: =TEAMGROWTH!#REF! -> #REF! | D129: =TEAMGROWTH!#REF! -> #REF! | E129: =TEAMGROWTH!#REF! -> #REF! | F129: =TEAMGROWTH!#REF! -> #REF! | G129: =TEAMGROWTH!#REF! -> #REF! | H129: =TEAMGROWTH!#REF! -> #REF! | ... M129: =TEAMGROWTH!#REF! -> #REF!
A130: =TEAMGROWTH!#REF! -> #REF! | B130: =TEAMGROWTH!#REF! -> #REF! | C130: =TEAMGROWTH!#REF! -> #REF! | D130: =TEAMGROWTH!#REF! -> #REF! | E130: =TEAMGROWTH!#REF! -> #REF! | F130: =TEAMGROWTH!#REF! -> #REF! | G130: =TEAMGROWTH!#REF! -> #REF! | H130: =TEAMGROWTH!#REF! -> #REF! | ... M130: =TEAMGROWTH!#REF! -> #REF!
A131: =TEAMGROWTH!#REF! -> #REF! | B131: =TEAMGROWTH!#REF! -> #REF! | C131: =TEAMGROWTH!#REF! -> #REF! | D131: =TEAMGROWTH!#REF! -> #REF! | E131: =TEAMGROWTH!#REF! -> #REF! | F131: =TEAMGROWTH!#REF! -> #REF! | G131: =TEAMGROWTH!#REF! -> #REF! | H131: =TEAMGROWTH!#REF! -> #REF! | ... M131: =TEAMGROWTH!#REF! -> #REF!
A132: =TEAMGROWTH!#REF! -> #REF! | B132: =TEAMGROWTH!#REF! -> #REF! | C132: =TEAMGROWTH!#REF! -> #REF! | D132: =TEAMGROWTH!#REF! -> #REF! | E132: =TEAMGROWTH!#REF! -> #REF! | F132: =TEAMGROWTH!#REF! -> #REF! | G132: =TEAMGROWTH!#REF! -> #REF! | H132: =TEAMGROWTH!#REF! -> #REF! | ... M132: =TEAMGROWTH!#REF! -> #REF!
A133: =TEAMGROWTH!#REF! -> #REF! | B133: =TEAMGROWTH!#REF! -> #REF! | C133: =TEAMGROWTH!#REF! -> #REF! | D133: =TEAMGROWTH!#REF! -> #REF! | E133: =TEAMGROWTH!#REF! -> #REF! | F133: =TEAMGROWTH!#REF! -> #REF! | G133: =TEAMGROWTH!#REF! -> #REF! | H133: =TEAMGROWTH!#REF! -> #REF! | ... M133: =TEAMGROWTH!#REF! -> #REF!
A134: =TEAMGROWTH!#REF! -> #REF! | B134: =TEAMGROWTH!#REF! -> #REF! | C134: =TEAMGROWTH!#REF! -> #REF! | D134: =TEAMGROWTH!#REF! -> #REF! | E134: =TEAMGROWTH!#REF! -> #REF! | F134: =TEAMGROWTH!#REF! -> #REF! | G134: =TEAMGROWTH!#REF! -> #REF! | H134: =TEAMGROWTH!#REF! -> #REF! | ... M134: =TEAMGROWTH!#REF! -> #REF!
A135: =TEAMGROWTH!#REF! -> #REF! | B135: =TEAMGROWTH!#REF! -> #REF! | C135: =TEAMGROWTH!#REF! -> #REF! | D135: =TEAMGROWTH!#REF! -> #REF! | E135: =TEAMGROWTH!#REF! -> #REF! | F135: =TEAMGROWTH!#REF! -> #REF! | G135: =TEAMGROWTH!#REF! -> #REF! | H135: =TEAMGROWTH!#REF! -> #REF! | ... M135: =TEAMGROWTH!#REF! -> #REF!
B138: ='2023 Forecast Totals'!D$3 -> Jan | C138: ='2023 Forecast Totals'!E$3 -> Feb | D138: ='2023 Forecast Totals'!F$3 -> Mar | E138: ='2023 Forecast Totals'!G$3 -> Apr | F138: ='2023 Forecast Totals'!H$3 -> May | G138: ='2023 Forecast Totals'!I$3 -> Jun | H138: ='2023 Forecast Totals'!J$3 -> Jul | I138: ='2023 Forecast Totals'!K$3 -> Aug | ... M138: ='2023 Forecast Totals'!O$3 -> Dec
A139: =TEAMGROWTH!D58 -> Drew Sandoval | B139: =TEAMGROWTH!L58 -> 164.56825 | C139: =TEAMGROWTH!N58 -> 164.56825 | D139: =TEAMGROWTH!P58 -> 164.56825 | E139: =TEAMGROWTH!R58 -> 164.56825 | F139: =TEAMGROWTH!T58 -> 164.56825 | G139: =TEAMGROWTH!V58 -> 164.56825 | H139: =TEAMGROWTH!X58 -> 164.56825 | I139: =TEAMGROWTH!Z58 -> 164.56825 | J139: =TEAMGROWTH!AB58 -> 164.56825 | K139: =TEAMGROWTH!AD58 -> 164.56825 | L139: =TEAMGROWTH!AF58 -> 164.56825 | M139: =TEAMGROWTH!AH58 -> 164.56825
A140: =TEAMGROWTH!#REF! -> #REF! | B140: =TEAMGROWTH!#REF! -> #REF! | C140: =TEAMGROWTH!#REF! -> #REF! | D140: =TEAMGROWTH!#REF! -> #REF! | E140: =TEAMGROWTH!#REF! -> #REF! | F140: =TEAMGROWTH!#REF! -> #REF! | G140: =TEAMGROWTH!#REF! -> #REF! | H140: =TEAMGROWTH!#REF! -> #REF! | ... M140: =TEAMGROWTH!#REF! -> #REF!
A141: =TEAMGROWTH!#REF! -> #REF! | B141: =TEAMGROWTH!#REF! -> #REF! | C141: =TEAMGROWTH!#REF! -> #REF! | D141: =TEAMGROWTH!#REF! -> #REF! | E141: =TEAMGROWTH!#REF! -> #REF! | F141: =TEAMGROWTH!#REF! -> #REF! | G141: =TEAMGROWTH!#REF! -> #REF! | H141: =TEAMGROWTH!#REF! -> #REF! | ... M141: =TEAMGROWTH!#REF! -> #REF!
A142: =TEAMGROWTH!#REF! -> #REF! | B142: =TEAMGROWTH!#REF! -> #REF! | C142: =TEAMGROWTH!#REF! -> #REF! | D142: =TEAMGROWTH!#REF! -> #REF! | E142: =TEAMGROWTH!#REF! -> #REF! | F142: =TEAMGROWTH!#REF! -> #REF! | G142: =TEAMGROWTH!#REF! -> #REF! | H142: =TEAMGROWTH!#REF! -> #REF! | ... M142: =TEAMGROWTH!#REF! -> #REF!
A143: =TEAMGROWTH!#REF! -> #REF! | B143: =TEAMGROWTH!#REF! -> #REF! | C143: =TEAMGROWTH!#REF! -> #REF! | D143: =TEAMGROWTH!#REF! -> #REF! | E143: =TEAMGROWTH!#REF! -> #REF! | F143: =TEAMGROWTH!#REF! -> #REF! | G143: =TEAMGROWTH!#REF! -> #REF! | H143: =TEAMGROWTH!#REF! -> #REF! | ... M143: =TEAMGROWTH!#REF! -> #REF!
A144: =TEAMGROWTH!#REF! -> #REF! | B144: =TEAMGROWTH!#REF! -> #REF! | C144: =TEAMGROWTH!#REF! -> #REF! | D144: =TEAMGROWTH!#REF! -> #REF! | E144: =TEAMGROWTH!#REF! -> #REF! | F144: =TEAMGROWTH!#REF! -> #REF! | G144: =TEAMGROWTH!#REF! -> #REF! | H144: =TEAMGROWTH!#REF! -> #REF! | ... M144: =TEAMGROWTH!#REF! -> #REF!
A145: =TEAMGROWTH!#REF! -> #REF! | B145: =TEAMGROWTH!#REF! -> #REF! | C145: =TEAMGROWTH!#REF! -> #REF! | D145: =TEAMGROWTH!#REF! -> #REF! | E145: =TEAMGROWTH!#REF! -> #REF! | F145: =TEAMGROWTH!#REF! -> #REF! | G145: =TEAMGROWTH!#REF! -> #REF! | H145: =TEAMGROWTH!#REF! -> #REF! | ... M145: =TEAMGROWTH!#REF! -> #REF!
A146: =TEAMGROWTH!#REF! -> #REF! | B146: =TEAMGROWTH!#REF! -> #REF! | C146: =TEAMGROWTH!#REF! -> #REF! | D146: =TEAMGROWTH!#REF! -> #REF! | E146: =TEAMGROWTH!#REF! -> #REF! | F146: =TEAMGROWTH!#REF! -> #REF! | G146: =TEAMGROWTH!#REF! -> #REF! | H146: =TEAMGROWTH!#REF! -> #REF! | ... M146: =TEAMGROWTH!#REF! -> #REF!
A147: =TEAMGROWTH!#REF! -> #REF! | B147: =TEAMGROWTH!#REF! -> #REF! | C147: =TEAMGROWTH!#REF! -> #REF! | D147: =TEAMGROWTH!#REF! -> #REF! | E147: =TEAMGROWTH!#REF! -> #REF! | F147: =TEAMGROWTH!#REF! -> #REF! | G147: =TEAMGROWTH!#REF! -> #REF! | H147: =TEAMGROWTH!#REF! -> #REF! | ... M147: =TEAMGROWTH!#REF! -> #REF!
A148: =TEAMGROWTH!#REF! -> #REF! | B148: =TEAMGROWTH!#REF! -> #REF! | C148: =TEAMGROWTH!#REF! -> #REF! | D148: =TEAMGROWTH!#REF! -> #REF! | E148: =TEAMGROWTH!#REF! -> #REF! | F148: =TEAMGROWTH!#REF! -> #REF! | G148: =TEAMGROWTH!#REF! -> #REF! | H148: =TEAMGROWTH!#REF! -> #REF! | ... M148: =TEAMGROWTH!#REF! -> #REF!
A149: =TEAMGROWTH!#REF! -> #REF! | B149: =TEAMGROWTH!#REF! -> #REF! | C149: =TEAMGROWTH!#REF! -> #REF! | D149: =TEAMGROWTH!#REF! -> #REF! | E149: =TEAMGROWTH!#REF! -> #REF! | F149: =TEAMGROWTH!#REF! -> #REF! | G149: =TEAMGROWTH!#REF! -> #REF! | H149: =TEAMGROWTH!#REF! -> #REF! | ... M149: =TEAMGROWTH!#REF! -> #REF!
A150: =TEAMGROWTH!#REF! -> #REF! | B150: =TEAMGROWTH!#REF! -> #REF! | C150: =TEAMGROWTH!#REF! -> #REF! | D150: =TEAMGROWTH!#REF! -> #REF! | E150: =TEAMGROWTH!#REF! -> #REF! | F150: =TEAMGROWTH!#REF! -> #REF! | G150: =TEAMGROWTH!#REF! -> #REF! | H150: =TEAMGROWTH!#REF! -> #REF! | ... M150: =TEAMGROWTH!#REF! -> #REF!
A151: =TEAMGROWTH!#REF! -> #REF! | B151: =TEAMGROWTH!#REF! -> #REF! | C151: =TEAMGROWTH!#REF! -> #REF! | D151: =TEAMGROWTH!#REF! -> #REF! | E151: =TEAMGROWTH!#REF! -> #REF! | F151: =TEAMGROWTH!#REF! -> #REF! | G151: =TEAMGROWTH!#REF! -> #REF! | H151: =TEAMGROWTH!#REF! -> #REF! | ... M151: =TEAMGROWTH!#REF! -> #REF!
A152: =TEAMGROWTH!#REF! -> #REF! | B152: =TEAMGROWTH!#REF! -> #REF! | C152: =TEAMGROWTH!#REF! -> #REF! | D152: =TEAMGROWTH!#REF! -> #REF! | E152: =TEAMGROWTH!#REF! -> #REF! | F152: =TEAMGROWTH!#REF! -> #REF! | G152: =TEAMGROWTH!#REF! -> #REF! | H152: =TEAMGROWTH!#REF! -> #REF! | ... M152: =TEAMGROWTH!#REF! -> #REF!
A154: Effective Techs
B155: ='2023 Forecast Totals'!D$3 -> Jan | C155: ='2023 Forecast Totals'!E$3 -> Feb | D155: ='2023 Forecast Totals'!F$3 -> Mar | E155: ='2023 Forecast Totals'!G$3 -> Apr | F155: ='2023 Forecast Totals'!H$3 -> May | G155: ='2023 Forecast Totals'!I$3 -> Jun | H155: ='2023 Forecast Totals'!J$3 -> Jul | I155: ='2023 Forecast Totals'!K$3 -> Aug | ... M155: ='2023 Forecast Totals'!O$3 -> Dec | N155: ='2023 Forecast Totals'!Q$3 -> Jan | O155: ='2023 Forecast Totals'!R$3 -> Feb | P155: ='2023 Forecast Totals'!S$3 -> Mar | Q155: ='2023 Forecast Totals'!T$3 -> Apr | R155: ='2023 Forecast Totals'!U$3 -> May | S155: ='2023 Forecast Totals'!V$3 -> Jun | T155: ='2023 Forecast Totals'!W$3 -> Jul | U155: ='2023 Forecast Totals'!X$3 -> Aug | ... X155: ='2023 Forecast Totals'!AA$3 -> Nov | Y155: Dec | Z155: ='2023 Forecast Totals'!AD$3 -> Jan | AA155: ='2023 Forecast Totals'!AE$3 -> Feb | AB155: ='2023 Forecast Totals'!AF$3 -> Mar | AC155: ='2023 Forecast Totals'!AG$3 -> Apr | AD155: ='2023 Forecast Totals'!AH$3 -> May | AE155: ='2023 Forecast Totals'!AI$3 -> Jun | AF155: ='2023 Forecast Totals'!AJ$3 -> Jul | AG155: ='2023 Forecast Totals'!AK$3 -> Aug | ... AK155: ='2023 Forecast Totals'!AO$3 -> Dec
A156: ='2023 Forecast Totals'!A43 -> Effective Techs | B156: ='2023 Forecast Totals'!D43 -> 20.8 | C156: ='2023 Forecast Totals'!E43 -> 20.8 | D156: ='2023 Forecast Totals'!F43 -> 20.8 | E156: ='2023 Forecast Totals'!G43 -> 20.8 | F156: ='2023 Forecast Totals'!H43 -> 20.8 | G156: ='2023 Forecast Totals'!I43 -> 20.8 | H156: ='2023 Forecast Totals'!J43 -> 20.8 | I156: ='2023 Forecast Totals'!K43 -> 20.8 | ... M156: ='2023 Forecast Totals'!O43 -> 20.8 | N156: ='2023 Forecast Totals'!Q43 -> 24 | O156: ='2023 Forecast Totals'!R43 -> 28.8 | P156: ='2023 Forecast Totals'!S43 -> 28.8 | Q156: ='2023 Forecast Totals'!T43 -> 28.8 | R156: ='2023 Forecast Totals'!U43 -> 28.8 | S156: ='2023 Forecast Totals'!V43 -> 28.8 | T156: ='2023 Forecast Totals'!W43 -> 28.8 | U156: ='2023 Forecast Totals'!X43 -> 24 | ... Y156: ='2023 Forecast Totals'!AB43 -> 24 | Z156: ='2023 Forecast Totals'!AD43 -> 24 | AA156: ='2023 Forecast Totals'!AE43 -> 24 | AB156: ='2023 Forecast Totals'!AF43 -> 24 | AC156: ='2023 Forecast Totals'!AG43 -> 24 | AD156: ='2023 Forecast Totals'!AH43 -> 24 | AE156: ='2023 Forecast Totals'!AI43 -> 24 | AF156: ='2023 Forecast Totals'!AJ43 -> 24 | AG156: ='2023 Forecast Totals'!AK43 -> 24 | ... AK156: ='2023 Forecast Totals'!AO43 -> 24
A157: ='Man Hours & Costs'!A4 -> BDU Actual Techs | B157: ='Man Hours & Costs'!C4 -> 26 | C157: ='Man Hours & Costs'!D4 -> 26 | D157: ='Man Hours & Costs'!E4 -> 26 | E157: ='Man Hours & Costs'!F4 -> 26 | F157: ='Man Hours & Costs'!G4 -> 26 | G157: ='Man Hours & Costs'!H4 -> 26 | H157: ='Man Hours & Costs'!I4 -> 26 | I157: ='Man Hours & Costs'!J4 -> 26 | ... M157: ='Man Hours & Costs'!N4 -> 26 | N157: ='Man Hours & Costs'!P4 -> 30 | O157: ='Man Hours & Costs'!Q4 -> 36 | P157: ='Man Hours & Costs'!R4 -> 36 | Q157: ='Man Hours & Costs'!S4 -> 36 | R157: ='Man Hours & Costs'!T4 -> 36 | S157: ='Man Hours & Costs'!U4 -> 36 | T157: ='Man Hours & Costs'!V4 -> 36 | U157: ='Man Hours & Costs'!W4 -> 30 | ... Y157: ='Man Hours & Costs'!AA4 -> 30 | Z157: ='Man Hours & Costs'!AC4 -> 30 | AA157: ='Man Hours & Costs'!AD4 -> 30 | AB157: ='Man Hours & Costs'!AE4 -> 30 | AC157: ='Man Hours & Costs'!AF4 -> 30 | AD157: ='Man Hours & Costs'!AG4 -> 30 | AE157: ='Man Hours & Costs'!AH4 -> 30 | AF157: ='Man Hours & Costs'!AI4 -> 30 | AG157: ='Man Hours & Costs'!AJ4 -> 30 | ... AK157: ='Man Hours & Costs'!AN4 -> 30
A159: Calibrated MH
...

Sheet Controls
C2: Billable time worksheet
D3: Mins | E3: Hours
C4: Time in day | D4: =E4*60 -> 480 | E4: 8
C5: Daily Breaks | D5: 30 | E5: =D5/60 -> 0.5
C6: Daily Lunches | E6: =D6/60 -> 0
C7: Daily Clean up | D7: 15 | E7: =D7/60 -> 0.25
C8: Daily Meetings | D8: 9 | E8: =D8/60 -> 0.15
C9: Total reduction | D9: =SUM(D5:D8)*-1 -> -54 | E9: =D9/60 -> -0.9
C11: Daily billiable | D11: ='Man Hours & Costs'!S4+D9 -> -18 | E11: =D11/60 -> -0.3
B12: Total time available for productive work | C12: Total billable time in day | D12: =D4+D11 -> 462 | E12: =D12/60 -> 7.7
C13: Total billable time with OT | D13: =D12+(D12*E15) -> 475.86 | E13: =D13/60 -> 7.931
C15: Overtime Assumption | E15: 0.03
C16: Work Buffer | E16: 0.1
C17: Total number of technicans BJC | D17: =COUNTA(TEAMGROWTH!D27:D43) -> 8
C18: Total number of tech SLC | D18: =COUNTA(TEAMGROWTH!D58:D63) -> 1
C19: Avalible time for billing | D19: Start billiable amount NEW TECH | E19: Change needed | F19: Months to fully billable | G19: Increase % per month | H19: Months to Average work load
C20: High | D20: 0.25 | E20: =D20-1 -> -0.75 | F20: 6 | G20: =(E20/F20)*-1*(1) -> 0.125 | H20: 9
C21: Medium | D21: 0.25 | E21: =D21-1 -> -0.75 | F21: 9 | G21: =(E21/F21)*-1 -> 0.083333333 | H21: 10.5
C22: Low | D22: 0.1 | E22: =D22-1 -> -0.9 | F22: 12 | G22: =(E22/F22)*-1 -> 0.075 | H22: 18
C23: Helper not on path to A&P - Extra Low | D23: 0 | E23: =D23-1 -> -1 | F23: 24 | G23: =(E23/F23)*-1 -> 0.041666667 | H23: 36
C24: Position reducitons | D24: Of total | E24: Mins | F24: Hours
C25: AP | D25: 0 | E25: =TEAMGROWTH!C23*D25 -> 0 | F25: =E25/60 -> 0
C26: CC - Crew Chief | D26: 0.7 | E26: =$D$13*D26 -> 333.102 | F26: =E26/60 -> 5.5517
C27: AV - Avionics Tech | D27: 0 | E27: =$D$13*D27 -> 0 | F27: =E27/60 -> 0
C28: AV CC - Avonics Crew Chief | D28: 0.6 | E28: =$D$13*D28 -> 285.516 | F28: =E28/60 -> 4.7586
C29: SF- Shop Foreman | D29: 0.5 | E29: =$D$13*D29 -> 237.93 | F29: =E29/60 -> 3.9655
C30: DOM | D30: 1 | E30: =$D$13*D30 -> 475.86 | F30: =E30/60 -> 7.931
C32: PTO
D34: January | E34: Febuary | F34: March | G34: April | H34: May | I34: June | J34: July | K34: August | L34: September | M34: October | N34: November | O34: December
C35: CO AV | D35: 8 | E35: 0 | F35: 0 | G35: 10.66 | H35: 0 | I35: 0 | J35: 5.33 | K35: 2.66 | L35: 2.66 | M35: 0 | N35: 8
C36: CA AV | D36: 26.66 | E36: 0 | F36: 21.3 | G36: 16 | H36: 0 | I36: 3.24 | J36: 24 | K36: 2.66 | L36: 8 | M36: 5.33 | N36: 12
C37: CO MX | D37: 11.59 | E37: 4.251 | F37: 4.91 | G37: 7.4 | H37: 12.42 | I37: 16.34 | J37: 4 | K37: 0 | L37: 15.2 | M37: 8.3 | N37: 3.8
C38: CA MX | D38: 10.66 | E38: 15.38 | F38: 5.38 | G38: 5.8 | H38: 4.5 | I38: 8 | J38: 16.69 | K38: 1 | L38: 6 | M38: 3.33 | N38: 31
C39: Total | D39: 14.2275 | E39: 4.90775 | F39: 7.8975 | G39: 9.965 | H39: 4.23 | I39: 6.895 | J39: 12.505 | K39: 1.58 | L39: 7.965 | M39: 4.24 | N39: 13.7 | O39: 0
Q40: Average hours per month per person excluding december | R40: 8.01025
Q41: Number of technicians | R41: 18
Q42: Total hours lost per month | R42: 144.1845
C43: Hangar Capacity | Q43: Total hours in 4 weeks (BJC 18 techs) | R43: 2880
Q44: % LOSS | R44: 0.050064063
C45: Monthly turn rate / bay 6 day turn | D45: 4 | Q45: Total person loss | R45: 0.9
...

Sheet Man Hours & Costs
A2: Paid Hours
C3: Jan | D3: Feb | E3: Mar | F3: Apr | G3: May | H3: Jun | I3: Jul | J3: Aug | K3: Sep | L3: Oct | M3: Nov | N3: Dec | O3: 2024 Totals | P3: Jan | Q3: Feb | R3: Mar | S3: Apr | T3: May | U3: Jun | V3: Jul | W3: Aug | X3: Sep | Y3: Oct | Z3: Nov | AA3: Dec | AB3: 2025 Totals | AC3: Jan | AD3: Feb | AE3: Mar | AF3: Apr | AG3: May | AH3: Jun | AI3: Jul | AJ3: Aug | AK3: Sep | AL3: Oct | AM3: Nov | AN3: Dec | AO3: 2026 Totals
A4: BDU Actual Techs | C4: ='2023 Forecast Totals'!D2 -> 26 | D4: ='2023 Forecast Totals'!E2 -> 26 | E4: ='2023 Forecast Totals'!F2 -> 26 | F4: ='2023 Forecast Totals'!G2 -> 26 | G4: ='2023 Forecast Totals'!H2 -> 26 | H4: ='2023 Forecast Totals'!I2 -> 26 | I4: ='2023 Forecast Totals'!J2 -> 26 | J4: ='2023 Forecast Totals'!K2 -> 26 | ... AO4: ='2023 Forecast Totals'!AP2 -> 30
A5: MH Hours paid per day | C5: 8 | D5: 8 | E5: 8 | F5: 8 | G5: 8 | H5: 8 | I5: 8 | J5: 8 | K5: 8 | L5: 8 | M5: 8 | N5: 8 | P5: 8 | Q5: 8 | R5: 8 | S5: 8 | T5: 8 | U5: 8 | V5: 8 | W5: 8 | X5: 8 | Y5: 8 | Z5: 8 | AA5: 8 | AC5: 8 | AD5: 8 | AE5: 8 | AF5: 8 | AG5: 8 | AH5: 8 | AI5: 8 | AJ5: 8 | AK5: 8 | AL5: 8 | AM5: 8 | AN5: 8
A6: Working days in month (minus holiday) | C6: 21 | D6: 20 | E6: 23 | F6: 20 | G6: 22 | H6: 22 | I6: 20 | J6: 23 | K6: 20 | L6: 22 | M6: 20 | N6: 16 | O6: =SUM(C6:N6) -> 249 | P6: 21 | Q6: 20 | R6: 23 | S6: 20 | T6: 22 | U6: 22 | V6: 20 | W6: 23 | X6: 20 | Y6: 22 | Z6: 20 | AA6: 16 | AB6: =SUM(P6:AA6) -> 249 | AC6: 21 | AD6: 20 | AE6: 23 | AF6: 20 | AG6: 22 | AH6: 22 | AI6: 20 | AJ6: 23 | AK6: 20 | AL6: 22 | AM6: 20 | AN6: 16 | AO6: =SUM(AC6:AN6) -> 249
A7: Paid holidays | B7: =B24 -> -54 | C7: 1 | G7: 1 | I7: 1 | M7: 1 | N7: 1 | P7: 1 | T7: 1 | V7: 1 | Z7: 1 | AA7: 1 | AC7: 1 | AG7: 1 | AI7: 1 | AM7: 1 | AN7: 1
A8: Total paid MH per day | C8: =C4*C5 -> 208 | D8: =D4*D5 -> 208 | E8: =E4*E5 -> 208 | F8: =F4*F5 -> 208 | G8: =G4*G5 -> 208 | H8: =H4*H5 -> 208 | I8: =I4*I5 -> 208 | J8: =J4*J5 -> 208 | ... N8: =N4*N5 -> 208 | P8: =P4*P5 -> 240 | Q8: =Q4*Q5 -> 288 | R8: =R4*R5 -> 288 | S8: =S4*S5 -> 288 | T8: =T4*T5 -> 288 | U8: =U4*U5 -> 288 | V8: =V4*V5 -> 288 | W8: =W4*W5 -> 240 | ... AA8: =AA4*AA5 -> 240 | AC8: =AC4*AC5 -> 240 | AD8: =AD4*AD5 -> 240 | AE8: =AE4*AE5 -> 240 | AF8: =AF4*AF5 -> 240 | AG8: =AG4*AG5 -> 240 | AH8: =AH4*AH5 -> 240 | AI8: =AI4*AI5 -> 240 | AJ8: =AJ4*AJ5 -> 240 | ... AN8: =AN4*AN5 -> 240
A9: Average Montly MH | C9: =C6*C8 -> 4368 | D9: =D6*D8 -> 4160 | E9: =E6*E8 -> 4784 | F9: =F6*F8 -> 4160 | G9: =G6*G8 -> 4576 | H9: =H6*H8 -> 4576 | I9: =I6*I8 -> 4160 | J9: =J6*J8 -> 4784 | ... N9: =N6*N8 -> 3328 | O9: =SUM(C9:N9) -> 51792 | P9: =P6*P8 -> 5040 | Q9: =Q6*Q8 -> 5760 | R9: =R6*R8 -> 6624 | S9: =S6*S8 -> 5760 | T9: =T6*T8 -> 6336 | U9: =U6*U8 -> 6336 | V9: =V6*V8 -> 5760 | W9: =W6*W8 -> 5520 | ... AA9: =AA6*AA8 -> 3840 | AB9: =SUM(P9:AA9) -> 65856 | AC9: =AC6*AC8 -> 5040 | AD9: =AD6*AD8 -> 4800 | AE9: =AE6*AE8 -> 5520 | AF9: =AF6*AF8 -> 4800 | AG9: =AG6*AG8 -> 5280 | AH9: =AH6*AH8 -> 5280 | AI9: =AI6*AI8 -> 4800 | AJ9: =AJ6*AJ8 -> 5520 | ... AN9: =AN6*AN8 -> 3840 | AO9: =SUM(AC9:AN9) -> 59760
A10: OT Assumption: | B10: =Controls!E15 -> 0.03
A11: Daily OT hours | C11: =C8*$B$10 -> 6.24 | D11: =D8*$B$10 -> 6.24 | E11: =E8*$B$10 -> 6.24 | F11: =F8*$B$10 -> 6.24 | G11: =G8*$B$10 -> 6.24 | H11: =H8*$B$10 -> 6.24 | I11: =I8*$B$10 -> 6.24 | J11: =J8*$B$10 -> 6.24 | ... N11: =N8*$B$10 -> 6.24 | O11: =SUM(C11:N11) -> 74.88 | P11: =P8*$B$10 -> 7.2 | Q11: =Q8*$B$10 -> 8.64 | R11: =R8*$B$10 -> 8.64 | S11: =S8*$B$10 -> 8.64 | T11: =T8*$B$10 -> 8.64 | U11: =U8*$B$10 -> 8.64 | V11: =V8*$B$10 -> 8.64 | W11: =W8*$B$10 -> 7.2 | ... AA11: =AA8*$B$10 -> 7.2 | AB11: =SUM(P11:AA11) -> 95.04 | AC11: =AC8*$B$10 -> 7.2 | AD11: =AD8*$B$10 -> 7.2 | AE11: =AE8*$B$10 -> 7.2 | AF11: =AF8*$B$10 -> 7.2 | AG11: =AG8*$B$10 -> 7.2 | AH11: =AH8*$B$10 -> 7.2 | AI11: =AI8*$B$10 -> 7.2 | AJ11: =AJ8*$B$10 -> 7.2 | ... AN11: =AN8*$B$10 -> 7.2 | AO11: =SUM(AC11:AN11) -> 86.4
A12: Monthly OT MH hours | C12: =C11*C6 -> 131.04 | D12: =D11*D6 -> 124.8 | E12: =E11*E6 -> 143.52 | F12: =F11*F6 -> 124.8 | G12: =G11*G6 -> 137.28 | H12: =H11*H6 -> 137.28 | I12: =I11*I6 -> 124.8 | J12: =J11*J6 -> 143.52 | ... N12: =N11*N6 -> 99.84 | O12: =SUM(C12:N12) -> 1553.76 | P12: =P11*P6 -> 151.2 | Q12: =Q11*Q6 -> 172.8 | R12: =R11*R6 -> 198.72 | S12: =S11*S6 -> 172.8 | T12: =T11*T6 -> 190.08 | U12: =U11*U6 -> 190.08 | V12: =V11*V6 -> 172.8 | W12: =W11*W6 -> 165.6 | ... AA12: =AA11*AA6 -> 115.2 | AB12: =SUM(P12:AA12) -> 1975.68 | AC12: =AC11*AC6 -> 151.2 | AD12: =AD11*AD6 -> 144 | AE12: =AE11*AE6 -> 165.6 | AF12: =AF11*AF6 -> 144 | AG12: =AG11*AG6 -> 158.4 | AH12: =AH11*AH6 -> 158.4 | AI12: =AI11*AI6 -> 144 | AJ12: =AJ11*AJ6 -> 165.6 | ... AN12: =AN11*AN6 -> 115.2 | AO12: =SUM(AC12:AN12) -> 1792.8
A13: paid hrs per day | C13: =C11+C8 -> 214.24 | D13: =D11+D8 -> 214.24 | E13: =E11+E8 -> 214.24 | F13: =F11+F8 -> 214.24 | G13: =G11+G8 -> 214.24 | H13: =H11+H8 -> 214.24 | I13: =I11+I8 -> 214.24 | J13: =J11+J8 -> 214.24 | ... N13: =N11+N8 -> 214.24 | P13: =P11+P8 -> 247.2 | Q13: =Q11+Q8 -> 296.64 | R13: =R11+R8 -> 296.64 | S13: =S11+S8 -> 296.64 | T13: =T11+T8 -> 296.64 | U13: =U11+U8 -> 296.64 | V13: =V11+V8 -> 296.64 | W13: =W11+W8 -> 247.2 | ... AA13: =AA11+AA8 -> 247.2 | AC13: =AC11+AC8 -> 247.2 | AD13: =AD11+AD8 -> 247.2 | AE13: =AE11+AE8 -> 247.2 | AF13: =AF11+AF8 -> 247.2 | AG13: =AG11+AG8 -> 247.2 | AH13: =AH11+AH8 -> 247.2 | AI13: =AI11+AI8 -> 247.2 | AJ13: =AJ11+AJ8 -> 247.2 | ... AN13: =AN11+AN8 -> 247.2
A14: Total paid hours monthly | C14: =(C4*C5*C6)+C12 -> 4499.04 | D14: =(D4*D5*D6)+D12 -> 4284.8 | E14: =(E4*E5*E6)+E12 -> 4927.52 | F14: =(F4*F5*F6)+F12 -> 4284.8 | G14: =(G4*G5*G6)+G12 -> 4713.28 | H14: =(H4*H5*H6)+H12 -> 4713.28 | I14: =(I4*I5*I6)+I12 -> 4284.8 | J14: =(J4*J5*J6)+J12 -> 4927.52 | ... N14: =(N4*N5*N6)+N12 -> 3427.84 | O14: =SUM(C14:N14) -> 53345.76 | P14: =(P4*P5*P6)+P12 -> 5191.2 | Q14: =(Q4*Q5*Q6)+Q12 -> 5932.8 | R14: =(R4*R5*R6)+R12 -> 6822.72 | S14: =(S4*S5*S6)+S12 -> 5932.8 | T14: =(T4*T5*T6)+T12 -> 6526.08 | U14: =(U4*U5*U6)+U12 -> 6526.08 | V14: =(V4*V5*V6)+V12 -> 5932.8 | W14: =(W4*W5*W6)+W12 -> 5685.6 | ... AA14: =(AA4*AA5*AA6)+AA12 -> 3955.2 | AB14: =SUM(P14:AA14) -> 67831.68 | AC14: =(AC4*AC5*AC6)+AC12 -> 5191.2 | AD14: =(AD4*AD5*AD6)+AD12 -> 4944 | AE14: =(AE4*AE5*AE6)+AE12 -> 5685.6 | AF14: =(AF4*AF5*AF6)+AF12 -> 4944 | AG14: =(AG4*AG5*AG6)+AG12 -> 5438.4 | AH14: =(AH4*AH5*AH6)+AH12 -> 5438.4 | AI14: =(AI4*AI5*AI6)+AI12 -> 4944 | AJ14: =(AJ4*AJ5*AJ6)+AJ12 -> 5685.6 | ... AN14: =(AN4*AN5*AN6)+AN12 -> 3955.2 | AO14: =SUM(AC14:AN14) -> 61552.8
A15: Utilization Assumption:
A16: Total possible billable hours | C16: =(Controls!$E$12*C4*C6)+(C12) -> 4335.24 | D16: =(Controls!$E$12*D4*D6)+(D12) -> 4128.8 | E16: =(Controls!$E$12*E4*E6)+(E12) -> 4748.12 | F16: =(Controls!$E$12*F4*F6)+(F12) -> 4128.8 | G16: =(Controls!$E$12*G4*G6)+(G12) -> 4541.68 | H16: =(Controls!$E$12*H4*H6)+(H12) -> 4541.68 | I16: =(Controls!$E$12*I4*I6)+(I12) -> 4128.8 | J16: =(Controls!$E$12*J4*J6)+(J12) -> 4748.12 | ... N16: =(Controls!$E$12*N4*N6)+(N12) -> 3303.04 | O16: =SUM(C16:N16) -> 51403.56 | P16: =(Controls!$E$12*P4*P6)+(P12) -> 5002.2 | Q16: =(Controls!$E$12*Q4*Q6)+(Q12) -> 5716.8 | R16: =(Controls!$E$12*R4*R6)+(R12) -> 6574.32 | S16: =(Controls!$E$12*S4*S6)+(S12) -> 5716.8 | T16: =(Controls!$E$12*T4*T6)+(T12) -> 6288.48 | U16: =(Controls!$E$12*U4*U6)+(U12) -> 6288.48 | V16: =(Controls!$E$12*V4*V6)+(V12) -> 5716.8 | W16: =(Controls!$E$12*W4*W6)+(W12) -> 5478.6 | ... AA16: =(Controls!$E$12*AA4*AA6)+(AA12) -> 3811.2 | AB16: =SUM(P16:AA16) -> 65362.08 | AC16: =(Controls!$E$12*AC4*AC6)+(AC12) -> 5002.2 | AD16: =(Controls!$E$12*AD4*AD6)+(AD12) -> 4764 | AE16: =(Controls!$E$12*AE4*AE6)+(AE12) -> 5478.6 | AF16: =(Controls!$E$12*AF4*AF6)+(AF12) -> 4764 | AG16: =(Controls!$E$12*AG4*AG6)+(AG12) -> 5240.4 | AH16: =(Controls!$E$12*AH4*AH6)+(AH12) -> 5240.4 | AI16: =(Controls!$E$12*AI4*AI6)+(AI12) -> 4764 | AJ16: =(Controls!$E$12*AJ4*AJ6)+(AJ12) -> 5478.6 | ... AN16: =(Controls!$E$12*AN4*AN6)+(AN12) -> 3811.2 | AO16: =SUM(AC16:AN16) -> 59311.8
A17: Utilization % of billable hours | C17: 0.8 | D17: 0.8 | E17: 0.8 | F17: 0.8 | G17: 0.8 | H17: 0.8 | I17: 0.8 | J17: 0.8 | K17: 0.8 | L17: 0.8 | M17: 0.8 | N17: 0.8 | O17: =AVERAGE(C17:N17) -> 0.8 | P17: 0.8 | Q17: 0.8 | R17: 0.8 | S17: 0.8 | T17: 0.8 | U17: 0.8 | V17: 0.8 | W17: 0.8 | X17: 0.8 | Y17: 0.8 | Z17: 0.8 | AA17: 0.8 | AB17: =AVERAGE(P17:AA17) -> 0.8 | AC17: 0.8 | AD17: 0.8 | AE17: 0.8 | AF17: 0.8 | AG17: 0.8 | AH17: 0.8 | AI17: 0.8 | AJ17: 0.8 | AK17: 0.8 | AL17: 0.8 | AM17: 0.8 | AN17: 0.8 | AO17: =AVERAGE(AC17:AN17) -> 0.8
A18: Correct number of 100% Technicians adding vlaue | C18: =C4*C17 -> 20.8 | D18: =D4*D17 -> 20.8 | E18: =E4*E17 -> 20.8 | F18: =F4*F17 -> 20.8 | G18: =G4*G17 -> 20.8 | H18: =H4*H17 -> 20.8 | I18: =I4*I17 -> 20.8 | J18: =J4*J17 -> 20.8 | ... N18: =N4*N17 -> 20.8 | O18: =AVERAGE(C18:N18) -> 20.8 | P18: =P4*P17 -> 24 | Q18: =Q4*Q17 -> 28.8 | R18: =R4*R17 -> 28.8 | S18: =S4*S17 -> 28.8 | T18: =T4*T17 -> 28.8 | U18: =U4*U17 -> 28.8 | V18: =V4*V17 -> 28.8 | W18: =W4*W17 -> 24 | ... AA18: =AA4*AA17 -> 24 | AB18: =AVERAGE(P18:AA18) -> 26.4 | AC18: =AC4*AC17 -> 24 | AD18: =AD4*AD17 -> 24 | AE18: =AE4*AE17 -> 24 | AF18: =AF4*AF17 -> 24 | AG18: =AG4*AG17 -> 24 | AH18: =AH4*AH17 -> 24 | AI18: =AI4*AI17 -> 24 | AJ18: =AJ4*AJ17 -> 24 | ... AN18: =AN4*AN17 -> 24 | AO18: =AVERAGE(AC18:AN18) -> 24
A19: Total PTO hours loss | B19: -8 | C19: =$B$19*C4 -> -208 | D19: =$B$19*D4 -> -208 | E19: =$B$19*E4 -> -208 | F19: =$B$19*F4 -> -208 | G19: =$B$19*G4 -> -208 | H19: =$B$19*H4 -> -208 | I19: =$B$19*I4 -> -208 | J19: =$B$19*J4 -> -208 | ... N19: =$B$19*N4 -> -208 | O19: =SUM(C19:N19) -> -2496 | P19: =$B$19*P4 -> -240 | Q19: =$B$19*Q4 -> -288 | R19: =$B$19*R4 -> -288 | S19: =$B$19*S4 -> -288 | T19: =$B$19*T4 -> -288 | U19: =$B$19*U4 -> -288 | V19: =$B$19*V4 -> -288 | W19: =$B$19*W4 -> -240 | ... AA19: =$B$19*AA4 -> -240 | AB19: =SUM(P19:AA19) -> -3168 | AC19: =$B$19*AC4 -> -240 | AD19: =$B$19*AD4 -> -240 | AE19: =$B$19*AE4 -> -240 | AF19: =$B$19*AF4 -> -240 | AG19: =$B$19*AG4 -> -240 | AH19: =$B$19*AH4 -> -240 | AI19: =$B$19*AI4 -> -240 | AJ19: =$B$19*AJ4 -> -240 | ... AN19: =$B$19*AN4 -> -240 | AO19: =SUM(AC19:AN19) -> -2880
A20: Total calibrated billable hours | C20: =(C16*C17)+C19 -> 3260.192 | D20: =(D16*D17)+D19 -> 3095.04 | E20: =(E16*E17)+E19 -> 3590.496 | F20: =(F16*F17)+F19 -> 3095.04 | G20: =(G16*G17)+G19 -> 3425.344 | H20: =(H16*H17)+H19 -> 3425.344 | I20: =(I16*I17)+I19 -> 3095.04 | J20: =(J16*J17)+J19 -> 3590.496 | ... N20: =(N16*N17)+N19 -> 2434.432 | O20: =SUM(C20:N20) -> 38626.848 | P20: =(P16*P17)+P19 -> 3761.76 | Q20: =(Q16*Q17)+Q19 -> 4285.44 | R20: =(R16*R17)+R19 -> 4971.456 | S20: =(S16*S17)+S19 -> 4285.44 | T20: =(T16*T17)+T19 -> 4742.784 | U20: =(U16*U17)+U19 -> 4742.784 | V20: =(V16*V17)+V19 -> 4285.44 | W20: =(W16*W17)+W19 -> 4142.88 | ... AA20: =(AA16*AA17)+AA19 -> 2808.96 | AB20: =SUM(P20:AA20) -> 49121.664 | AC20: =(AC16*AC17)+AC19 -> 3761.76 | AD20: =(AD16*AD17)+AD19 -> 3571.2 | AE20: =(AE16*AE17)+AE19 -> 4142.88 | AF20: =(AF16*AF17)+AF19 -> 3571.2 | AG20: =(AG16*AG17)+AG19 -> 3952.32 | AH20: =(AH16*AH17)+AH19 -> 3952.32 | AI20: =(AI16*AI17)+AI19 -> 3571.2 | AJ20: =(AJ16*AJ17)+AJ19 -> 4142.88 | ... AN20: =(AN16*AN17)+AN19 -> 2808.96 | AO20: =SUM(AC20:AN20) -> 44569.44
A22: Costs
A23: Cost of holiday | C23: =$B$7*C4*C5 -> -11232 | D23: 0 | E23: 0 | F23: 0 | G23: =$B$7*G4*G5 -> -11232 | H23: 0 | I23: =$B$7*I4*I5 -> -11232 | J23: 0 | K23: 0 | L23: 0 | M23: =$B$7*M4*M5 -> -11232 | N23: =$B$7*N4*N5 -> -11232 | O23: 0 | P23: =$B$7*P4*P5 -> -12960 | Q23: 0 | R23: 0 | S23: 0 | T23: =$B$7*T4*T5 -> -15552 | U23: 0 | V23: =$B$7*V4*V5 -> -15552 | W23: 0 | X23: 0 | Y23: 0 | Z23: =$B$7*Z4*Z5 -> -12960 | AA23: =$B$7*AA4*AA5 -> -12960 | AB23: 0 | AC23: =$B$7*AC4*AC5 -> -12960 | AD23: 0 | AE23: 0 | AF23: 0 | AG23: =$B$7*AG4*AG5 -> -12960 | AH23: 0 | AI23: =$B$7*AI4*AI5 -> -12960 | AJ23: 0 | AK23: 0 | AL23: 0 | AM23: =$B$7*AM4*AM5 -> -12960 | AN23: =$B$7*AN4*AN5 -> -12960 | AO23: 0
A24: Average Daily MH Cost | B24: =Controls!D59 -> -54 | C24: =$B$24*C8 -> -11232 | D24: =$B$24*D8 -> -11232 | E24: =$B$24*E8 -> -11232 | F24: =$B$24*F8 -> -11232 | G24: =$B$24*G8 -> -11232 | H24: =$B$24*H8 -> -11232 | I24: =$B$24*I8 -> -11232 | J24: =$B$24*J8 -> -11232 | ... N24: =$B$24*N8 -> -11232 | O24: =SUM(C24:N24) -> -134784 | P24: =$B$24*P8 -> -12960 | Q24: =$B$24*Q8 -> -15552 | R24: =$B$24*R8 -> -15552 | S24: =$B$24*S8 -> -15552 | T24: =$B$24*T8 -> -15552 | U24: =$B$24*U8 -> -15552 | V24: =$B$24*V8 -> -15552 | W24: =$B$24*W8 -> -12960 | ... AA24: =$B$24*AA8 -> -12960 | AB24: =SUM(P24:AA24) -> -171072 | AC24: =$B$24*AC8 -> -12960 | AD24: =$B$24*AD8 -> -12960 | AE24: =$B$24*AE8 -> -12960 | AF24: =$B$24*AF8 -> -12960 | AG24: =$B$24*AG8 -> -12960 | AH24: =$B$24*AH8 -> -12960 | AI24: =$B$24*AI8 -> -12960 | AJ24: =$B$24*AJ8 -> -12960 | ... AN24: =$B$24*AN8 -> -12960 | AO24: =SUM(AC24:AN24) -> -155520
A25: Average Daily OT MH Cost | B25: =B24*1.5 -> -81 | C25: =$B$25*C11 -> -505.44 | D25: =$B$25*D11 -> -505.44 | E25: =$B$25*E11 -> -505.44 | F25: =$B$25*F11 -> -505.44 | G25: =$B$25*G11 -> -505.44 | H25: =$B$25*H11 -> -505.44 | I25: =$B$25*I11 -> -505.44 | J25: =$B$25*J11 -> -505.44 | ... N25: =$B$25*N11 -> -505.44 | O25: =SUM(C25:N25) -> -6065.28 | P25: =$B$25*P11 -> -583.2 | Q25: =$B$25*Q11 -> -699.84 | R25: =$B$25*R11 -> -699.84 | S25: =$B$25*S11 -> -699.84 | T25: =$B$25*T11 -> -699.84 | U25: =$B$25*U11 -> -699.84 | V25: =$B$25*V11 -> -699.84 | W25: =$B$25*W11 -> -583.2 | ... AA25: =$B$25*AA11 -> -583.2 | AB25: =SUM(P25:AA25) -> -7698.24 | AC25: =$B$25*AC11 -> -583.2 | AD25: =$B$25*AD11 -> -583.2 | AE25: =$B$25*AE11 -> -583.2 | AF25: =$B$25*AF11 -> -583.2 | AG25: =$B$25*AG11 -> -583.2 | AH25: =$B$25*AH11 -> -583.2 | AI25: =$B$25*AI11 -> -583.2 | AJ25: =$B$25*AJ11 -> -583.2 | ... AN25: =$B$25*AN11 -> -583.2 | AO25: =SUM(AC25:AN25) -> -6998.4
A26: Average Monthly MH cost | B26: =B24 -> -54 | C26: =C9*$B$26 -> -235872 | D26: =D9*$B$26 -> -224640 | E26: =E9*$B$26 -> -258336 | F26: =F9*$B$26 -> -224640 | G26: =G9*$B$26 -> -247104 | H26: =H9*$B$26 -> -247104 | I26: =I9*$B$26 -> -224640 | J26: =J9*$B$26 -> -258336 | ... N26: =N9*$B$26 -> -179712 | O26: =SUM(C26:N26) -> -2796768 | P26: =P9*$B$26 -> -272160 | Q26: =Q9*$B$26 -> -311040 | R26: =R9*$B$26 -> -357696 | S26: =S9*$B$26 -> -311040 | T26: =T9*$B$26 -> -342144 | U26: =U9*$B$26 -> -342144 | V26: =V9*$B$26 -> -311040 | W26: =W9*$B$26 -> -298080 | ... AA26: =AA9*$B$26 -> -207360 | AB26: =SUM(P26:AA26) -> -3556224 | AC26: =AC9*$B$26 -> -272160 | AD26: =AD9*$B$26 -> -259200 | AE26: =AE9*$B$26 -> -298080 | AF26: =AF9*$B$26 -> -259200 | AG26: =AG9*$B$26 -> -285120 | AH26: =AH9*$B$26 -> -285120 | AI26: =AI9*$B$26 -> -259200 | AJ26: =AJ9*$B$26 -> -298080 | ... AN26: =AN9*$B$26 -> -207360 | AO26: =SUM(AC26:AN26) -> -3227040
A27: Average Monthly Hour Cost | B27: =B25 -> -81 | C27: =$B$27*C12 -> -10614.24 | D27: =$B$27*D12 -> -10108.8 | E27: =$B$27*E12 -> -11625.12 | F27: =$B$27*F12 -> -10108.8 | G27: =$B$27*G12 -> -11119.68 | H27: =$B$27*H12 -> -11119.68 | I27: =$B$27*I12 -> -10108.8 | J27: =$B$27*J12 -> -11625.12 | ... N27: =$B$27*N12 -> -8087.04 | O27: =SUM(C27:N27) -> -125854.56 | P27: =$B$27*P12 -> -12247.2 | Q27: =$B$27*Q12 -> -13996.8 | R27: =$B$27*R12 -> -16096.32 | S27: =$B$27*S12 -> -13996.8 | T27: =$B$27*T12 -> -15396.48 | U27: =$B$27*U12 -> -15396.48 | V27: =$B$27*V12 -> -13996.8 | W27: =$B$27*W12 -> -13413.6 | ... AA27: =$B$27*AA12 -> -9331.2 | AB27: =SUM(P27:AA27) -> -160030.08 | AC27: =$B$27*AC12 -> -12247.2 | AD27: =$B$27*AD12 -> -11664 | AE27: =$B$27*AE12 -> -13413.6 | AF27: =$B$27*AF12 -> -11664 | AG27: =$B$27*AG12 -> -12830.4 | AH27: =$B$27*AH12 -> -12830.4 | AI27: =$B$27*AI12 -> -11664 | AJ27: =$B$27*AJ12 -> -13413.6 | ... AN27: =$B$27*AN12 -> -9331.2 | AO27: =SUM(AC27:AN27) -> -145216.8
A28: Executive Overhead | O28: =SUM(C28:N28) -> 0 | AB28: =SUM(P28:AA28) -> 0 | AO28: =SUM(AC28:AN28) -> 0
A29: Non-billable investments Sam S. | O29: =SUM(C29:N29) -> 0 | AB29: =SUM(P29:AA29) -> 0 | AO29: =SUM(AC29:AN29) -> 0
A30: Detailer / Line service Lead | O30: =SUM(C30:N30) -> 0 | AB30: =SUM(P30:AA30) -> 0 | AO30: =SUM(AC30:AN30) -> 0
A31: Detailer / Line service | O31: =SUM(C31:N31) -> 0 | AB31: =SUM(P31:AA31) -> 0 | AO31: =SUM(AC31:AN31) -> 0
A32: Parts Clerk | O32: =SUM(C32:N32) -> 0 | AB32: =SUM(P32:AA32) -> 0 | AO32: =SUM(AC32:AN32) -> 0
